Workbook

Sheet 📋 Cover & Index
A2: Test Company
A3: Monthly Controller Reporting Model
A4: Powered by Cin7 Core | Multi-Channel Ecommerce & Wholesale
A5: Data Period: March – November 2025 | Generated: Thu Mar 12 2026
A8: PERFORMANCE SNAPSHOT
A9: Total Revenue | C9: Gross Profit | E9: Gross Margin % | G9: Net Contribution
A10: ='KPI Dashboard'!B5 -> 0 | C10: ='KPI Dashboard'!D6 -> 0 | E10: ='KPI Dashboard'!B7 -> - | G10: ='KPI Dashboard'!D7 -> 0
A11: INVENTORY ALERTS → 🔴 Critical: 0 | 🟡 Low Stock: 1 | 🟢 Healthy: 3 | 🔵 Overstock: 4
A13: WORKBOOK INDEX
A14: # | B14: Sheet Name | C14: Type | D14: Purpose | E14: Updated By | F14: Frequency | G14: Data Source | H14: Status
A15: 1 | B15: Cost Inputs | C15: 📝 Input | D15: Manual entry of Ad Spend (by channel) and Warehouse/Fulfillment costs by month | E15: Controller | F15: Monthly | G15: Accounting Invoices | H15: ✅ Active
A16: 2 | B16: Sales Trend Analysis | C16: 📊 Analysis | D16: Revenue, COGS, Gross Profit & MoM Growth % across 6 channels × 6 months | E16: Auto | F16: Monthly | G16: Cin7 Core Export | H16: ✅ Active
A17: 3 | B17: Product Margin Analysis | C17: 📊 Analysis | D17: Revenue, COGS, GM%, Avg Sell Price & Avg COGS per unit by SKU and Category | E17: Auto | F17: Monthly | G17: Cin7 Core Export | H17: ✅ Active
A18: 4 | B18: COGS & Profitability by Channel | C18: 📊 Analysis | D18: Product × Channel revenue & COGS matrix with GM% per channel | E18: Auto | F18: Monthly | G18: Cin7 Core Export | H18: ✅ Active
A19: 5 | B19: Inventory & MOS Analysis | C19: 📦 Inventory | D19: Current stock by location, 3-month avg velocity, MOS calculation & 🔴🟡🟢🔵 alerts | E19: Auto | F19: Weekly | G19: Cin7 Core Export | H19: ✅ Active
A20: 6 | B20: Inventory Movements | C20: 📦 Inventory | D20: Units Sold, Units Purchased & Net Movement per SKU across all months | E20: Auto | F20: Monthly | G20: Cin7 Core + Purchase Data | H20: ✅ Active
A21: 7 | B21: Sales Dashboard | C21: 📈 Dashboard | D21: 3 visual charts: Revenue by Channel (bar), Monthly Trend (line), Product Mix (pie) | E21: Auto | F21: Monthly | G21: Calculated Sheets | H21: ✅ Active
A22: 8 | B22: Profitability Dashboard | C22: 📈 Dashboard | D22: Full P&L waterfall: Revenue → COGS → Gross Profit → Ad Spend → Fulfillment → Net Contribution | E22: Auto | F22: Monthly | G22: Calculated + Cost Inputs | H22: ✅ Active
A23: 9 | B23: KPI Dashboard | C23: 🎯 Executive | D23: One-page scorecard: Revenue, Margins, Channel Mix, Top Products, Inventory Alerts | E23: Auto | F23: Monthly | G23: All Sheets | H23: ✅ Active
A24: 10 | B24: Weekly Order Tracker | C24: ⚠️ Risk | D24: Invoice & shipment status breakdown, revenue at risk (Draft/Unshipped), monthly activity summary | E24: Auto | F24: Weekly | G24: Cin7 Core Export | H24: ✅ Active
A25: — | B25: Sales Transactions Raw Data | C25: 🗄️ Raw Data | D25: Source: Cin7 Core sales export — DO NOT EDIT. Paste new data here monthly | E25: Controller | F25: Monthly | G25: Cin7 Core | H25: 📥 Paste Here
A26: — | B26: Inventory On Hand Raw Data | C26: 🗄️ Raw Data | D26: Source: Cin7 Core inventory snapshot — DO NOT EDIT. Paste new data here | E26: Controller | F26: Weekly | G26: Cin7 Core | H26: 📥 Paste Here
A27: — | B27: Purchase Transactions Raw data | C27: 🗄️ Raw Data | D27: Source: Cin7 Core purchase export — DO NOT EDIT. Paste new data here monthly | E27: Controller | F27: Monthly | G27: Cin7 Core | H27: 📥 Paste Here
A30: CONTROLLER RECOMMENDATIONS & INSIGHTS
A31: # | B31: Category | C31: Finding | D31: Recommendation | E31: Priority | F31: Owner | G31: Action By | H31: Status
A32: 1 | B32: 💰 Revenue Mix | C32: Shopify Web is the largest single Finished Goods channel by coded SKU revenue. Amazon is 2nd but has the widest SKU distribution. | D32: Increase Amazon PPC investment and expand SKU listings. Consider Amazon Subscribe & Save for recurring revenue. | E32: 🔴 High | F32: Marketing | G32: Monthly | H32: 🔲 Open
A33: 2 | B33: 📦 Inventory - Starter 4pk | C33: Ola-Mate-SP1-16oz-4pk shows 0 stock at NJ, NY & NOBL warehouses. Only 0 units at Founders. Selling at 68% GM — your highest-margin SKU. | D33: Prioritise replenishment of the 4pk immediately. High margin + low stock = missed revenue opportunity. | E33: 🔴 High | F33: Ops / Supply Chain | G33: ASAP | H33: 🔲 Open
A34: 3 | B34: 📦 Inventory - 12pk Variety | C34: VP1-16oz-12pk has only 54 units on hand across Amazon FBA (54) — no stock at Founders or warehouses. Best-selling SKU by revenue. | D34: Urgent reorder. Run production/co-pack planning now. Consider holding a 2-month safety stock minimum. | E34: 🔴 High | F34: Ops / Supply Chain | G34: ASAP | H34: 🔲 Open
A35: 4 | B35: 📦 Inventory - Overstock | C35: Loose cans (BC, GG, R) at NJ Warehouse: 3,162–3,162 units. MOS likely >6 months. Powder Blends at MZ: 1,000 units each with zero sales recorded. | D35: Review slow-mover strategy for loose cans and Powder Blends. Consider bundling, sampling, or promotional pricing to move stock. | E35: 🟡 Medium | F35: Sales / Marketing | G35: 30 days | H35: 🔲 Open
A36: 5 | B36: 💸 Ad Spend Tracking | C36: Cost Inputs sheet is unpopulated — Ad Spend and Fulfillment costs are $0. Net Contribution currently equals Gross Profit, overstating true profitability. | D36: Enter monthly ad spend (Amazon Ads, Shopify/Google, TikTok) and 3PL/fulfillment invoices into 'Cost Inputs' sheet immediately. | E36: 🔴 High | F36: Controller | G36: This Month | H36: 🔲 Open
A37: 6 | B37: 📊 Gross Margin by SKU | C37: Starter 4pk (68.3%) and Loose Cans (55.5%) have significantly higher margins than the 12pk variety packs (~23–41%). Grapefruit Ginger 12pk is lowest at 23.1%. | D37: Run profitability-weighted product mix analysis. Shift marketing spend toward highest-margin SKUs. Investigate COGS on GG 12pk. | E37: 🟡 Medium | F37: Finance | G37: Next Month | H37: 🔲 Open
A38: 7 | B38: 🏪 Channel Profitability | C38: Wholesale (channel 3890849) shows $478 revenue — very early stage. POS is $77. These channels have near-zero volume but positive margin. | D38: Define minimum order quantities and pricing floors for wholesale. Build a wholesale P&L proforma before scaling. | E38: 🟡 Medium | F38: Sales | G38: 60 days | H38: 🔲 Open
A39: 8 | B39: 🔄 Subscription Revenue | C39: Subscriptions channel shows only $100 revenue (1 line). Subscription revenue should be the highest-LTV channel for a beverage brand. | D39: Audit subscription setup on Shopify. Consider a dedicated subscription discount + flavour rotation to grow recurring base. | E39: 🟡 Medium | F39: Marketing | G39: 30 days | H39: 🔲 Open
A40: 9 | B40: 📑 Draft Invoice Risk | C40: Weekly Order Tracker will flag any Draft invoices in the data. Uninvoiced orders represent recognised revenue not yet legally billed. | D40: Implement a weekly close process: convert all Draft invoices to Invoiced before month-end. Controller to review every Friday. | E40: 🟡 Medium | F40: Controller | G40: Weekly | H40: 🔲 Open
A41: 10 | B41: 📈 Data Freshness | C41: Current data spans March–November 2025 with gaps (Apr–Jun missing). MOS calculations use Sep–Nov as the 3-month window. | D41: Ensure Cin7 exports are complete and sequential. Update Month references in Inventory & MOS Analysis sheet each quarter. Add Dec 2025 data when available. | E41: 🟢 Low | F41: Controller | G41: Ongoing | H41: 🔲 Open
A42: 11 | B42: 🔧 Model Maintenance | C42: Powder Blends SKUs show $0 revenue and zero sales. Either not yet launched or data not captured. | D42: Confirm launch status of Powder Blends. If live, verify Cin7 SKU mapping matches model (Ola-Mate-POW-* wildcard). | E42: 🟢 Low | F42: Controller | G42: Verify | H42: 🔲 Open
A43: 12 | B43: 📊 KPI Benchmarking | C43: Current blended GM% is 37.7% on Finished Goods. No prior period to benchmark against. | D43: Establish monthly GM% targets by channel. Set 40%+ as target for Finished Goods blended GM. Track vs actuals in KPI Dashboard. | E43: 🟢 Low | F43: Finance | G43: Q1 Planning | H43: 🔲 Open
A45: HOW TO REFRESH THIS MODEL (Monthly Process)
A46: Step | B46: Action | C46: Detail
A47: Step 1 | B47: Export from Cin7 Core | C47: Run: Sales by Product Details report → export to CSV. Paste into 'Sales Transactions Raw Data' tab (replace all rows, keep headers).
...

Sheet KPI Dashboard
A1: OlaMate — Controller KPI Dashboard
A2: All-period summary | Finished Goods only | Update month references in Sales Trend Analysis as new data flows in
A4: REVENUE & PROFITABILITY
A5: Total Revenue (All Channels) | B5: =SUMIFS('Sales Transactions Raw Data'!V:V,'Sales Transactions Raw Data'!J:J,"Finished Goods") -> 0 | C5: Total Units Sold | D5: =SUMIFS('Sales Transactions Raw Data'!T:T,'Sales Transactions Raw Data'!J:J,"Finished Goods") -> 0
A6: Total COGS | B6: =SUMIFS('Sales Transactions Raw Data'!W:W,'Sales Transactions Raw Data'!J:J,"Finished Goods") -> 0 | C6: Gross Profit | D6: =B5-B6 -> 0
A7: Amazon FBA | B7: Ola-Mate-VP1-16oz-12pk | C7: 16oz Variety 12pk | D7: Case | E7: 450 | F7: 50 | G7: 200 | H7: 100 | I7: 18.5 | J7: 450 | K7: 400
A8: Founders | B8: Ola-Mate-VP1-16oz-12pk | C8: 16oz Variety 12pk | D8: Case | E8: 320 | F8: 20 | G8: 0 | H8: 0 | I8: 18.5 | J8: 320 | K8: 300
A9: NJ Warehouse | B9: Ola-Mate-VP1-16oz-12pk | C9: 16oz Variety 12pk | D9: Case | E9: 1200 | F9: 150 | G9: 500 | H9: 200 | I9: 18.5 | J9: 1200 | K9: 1050
A10: Amazon FBA | B10: Ola-Mate-BC-16oz-12PK | C10: 16oz Berry Coconut 12pk | D10: Case | E10: 580 | F10: 80 | G10: 150 | H10: 50 | I10: 17.2 | J10: 580 | K10: 500
A11: Founders | B11: Ola-Mate-BC-16oz-12PK | C11: 16oz Berry Coconut 12pk | D11: Case | E11: 240 | F11: 10 | G11: 0 | H11: 0 | I11: 17.2 | J11: 240 | K11: 230
A12: NJ Warehouse | B12: Ola-Mate-BC-16oz-12PK | C12: 16oz Berry Coconut 12pk | D12: Case | E12: 890 | F12: 90 | G12: 300 | H12: 100 | I12: 17.2 | J12: 890 | K12: 800
A13: Amazon FBA | B13: Ola-Mate-GG-16oz-12pk | C13: 16oz Ginger Peach 12pk | D13: Case | E13: 420 | F13: 40 | G13: 100 | H13: 50 | I13: 17.5 | J13: 420 | K13: 380
A14: Founders | B14: Ola-Mate-GG-16oz-12pk | C14: 16oz Ginger Peach 12pk | D14: Case | E14: 180 | F14: 15 | G14: 0 | H14: 0 | I14: 17.5 | J14: 180 | K14: 165
A15: NJ Warehouse | B15: Ola-Mate-GG-16oz-12pk | C15: 16oz Ginger Peach 12pk | D15: Case | E15: 750 | F15: 60 | G15: 250 | H15: 80 | I15: 17.5 | J15: 750 | K15: 690
A16: Amazon FBA | B16: Ola-Mate-R-16oz-12pk | C16: 16oz Mint Lime 12pk | D16: Case | E16: 390 | F16: 30 | G16: 100 | H16: 0 | I16: 16.8 | J16: 390 | K16: 360
A17: NJ Warehouse | B17: Ola-Mate-R-16oz-12pk | C17: 16oz Original Mate 12pk | D17: Case | E17: 920 | F17: 100 | G17: 400 | H17: 150 | I17: 16.5 | J17: 920 | K17: 820

Sheet Weekly Order Tracker
A1: Weekly Order Tracker — Open Items & Risk Flags
A2: Tracks open/pending orders by invoice & shipment status | Update 'As Of Date' in B3 each week
A3: As Of Date (Today): | B3: =TODAY() -> 46267
A5: ORDER STATUS SUMMARY
A6: Status | B6: # Orders | C6: Revenue Value | D6: % of Total | E6: COGS | F6: Gross Profit
A7: 2027 | B7: 2027-08 | C7: Pacific Beverage Bottlers | D7: 2027-08-01 | E7: August | F7: INV-August | G7: VNC Brand | H7: General Goods | I7: Finished Goods | J7: SKU-2026 | K7: Cin7 Raw Material (August) | L7: each | M7: Main Warehouse | N7: BATCH-2026 | O7: INV-PB-101 | P7: 1 | Q7: NaN | R7: 0 | S7: 0 | T7: 0
A8: 2027 | B8: 2027-08 | C8: Pacific Beverage Bottlers | D8: 2027-08-01 | E8: August | F8: INV-August | G8: VNC Brand | H8: General Goods | I8: Finished Goods | J8: SKU-2026 | K8: Cin7 Raw Material (August) | L8: each | M8: Main Warehouse | N8: BATCH-2026 | O8: INV-PB-102 | P8: 1 | Q8: NaN | R8: 0 | S8: 0 | T8: 0

Sheet Sales Trend Analysis
A1: Sales Trend Analysis — Monthly by Channel
A3: REVENUE BY CHANNEL ($) | B3: 46106 | C3: 46228 | D3: 46259 | E3: 46290 | F3: 46320 | G3: 46351 | H3: 46381 | I3: 46048 | J3: 46079 | K3: 46107 | L3: Total
A4: Amazon (Seller Central) | B4: =SUMIFS('Sales Transactions Raw Data'!V:V,'Sales Transactions Raw Data'!S:S,"amazon",'Sales Transactions Raw Data'!B:B,"March",'Sales Transactions Raw Data'!A:A,2025,'Sales Transactions Raw Data'!J:J,"Finished Goods") -> 0 | C4: =SUMIFS('Sales Transactions Raw Data'!V:V,'Sales Transactions Raw Data'!S:S,"amazon",'Sales Transactions Raw Data'!B:B,"March",'Sales Transactions Raw Data'!A:A,2025,'Sales Transactions Raw Data'!J:J,"Finished Goods") -> 0 | D4: =SUMIFS('Sales Transactions Raw Data'!V:V,'Sales Transactions Raw Data'!S:S,"amazon",'Sales Transactions Raw Data'!B:B,"July",'Sales Transactions Raw Data'!A:A,2025,'Sales Transactions Raw Data'!J:J,"Finished Goods") -> 0 | E4: =SUMIFS('Sales Transactions Raw Data'!V:V,'Sales Transactions Raw Data'!S:S,"amazon",'Sales Transactions Raw Data'!B:B,"August",'Sales Transactions Raw Data'!A:A,2025,'Sales Transactions Raw Data'!J:J,"Finished Goods") -> 0 | F4: =SUMIFS('Sales Transactions Raw Data'!V:V,'Sales Transactions Raw Data'!S:S,"amazon",'Sales Transactions Raw Data'!B:B,"September",'Sales Transactions Raw Data'!A:A,2025,'Sales Transactions Raw Data'!J:J,"Finished Goods") -> 0 | G4: =SUMIFS('Sales Transactions Raw Data'!V:V,'Sales Transactions Raw Data'!S:S,"amazon",'Sales Transactions Raw Data'!B:B,"October",'Sales Transactions Raw Data'!A:A,2025,'Sales Transactions Raw Data'!J:J,"Finished Goods") -> 0 | H4: =SUMIFS('Sales Transactions Raw Data'!V:V,'Sales Transactions Raw Data'!S:S,"amazon",'Sales Transactions Raw Data'!B:B,"November",'Sales Transactions Raw Data'!A:A,2025,'Sales Transactions Raw Data'!J:J,"Finished Goods") -> 0 | I4: =SUMIFS('Sales Transactions Raw Data'!V:V,'Sales Transactions Raw Data'!S:S,"amazon",'Sales Transactions Raw Data'!B:B,"January",'Sales Transactions Raw Data'!A:A,2026,'Sales Transactions Raw Data'!J:J,"Finished Goods") -> 0 | J4: =SUMIFS('Sales Transactions Raw Data'!V:V,'Sales Transactions Raw Data'!S:S,"amazon",'Sales Transactions Raw Data'!B:B,"February",'Sales Transactions Raw Data'!A:A,2026,'Sales Transactions Raw Data'!J:J,"Finished Goods") -> 0 | K4: =SUMIFS('Sales Transactions Raw Data'!V:V,'Sales Transactions Raw Data'!S:S,"amazon",'Sales Transactions Raw Data'!B:B,"March",'Sales Transactions Raw Data'!A:A,2026,'Sales Transactions Raw Data'!J:J,"Finished Goods") -> 0 | L4: =SUM(B4:K4) -> 0
A5: Amazon Retail / Vendor | B5: =SUMIFS('Sales Transactions Raw Data'!V:V,'Sales Transactions Raw Data'!R:R,"Amazon.com",'Sales Transactions Raw Data'!B:B,"March",'Sales Transactions Raw Data'!A:A,2025,'Sales Transactions Raw Data'!J:J,"Finished Goods") -> 0 | C5: =SUMIFS('Sales Transactions Raw Data'!V:V,'Sales Transactions Raw Data'!S:S,"amazon-us",'Sales Transactions Raw Data'!B:B,"March",'Sales Transactions Raw Data'!A:A,2025,'Sales Transactions Raw Data'!J:J,"Finished Goods") -> 0 | D5: =SUMIFS('Sales Transactions Raw Data'!V:V,'Sales Transactions Raw Data'!S:S,"amazon-us",'Sales Transactions Raw Data'!B:B,"July",'Sales Transactions Raw Data'!A:A,2025,'Sales Transactions Raw Data'!J:J,"Finished Goods") -> 0 | E5: =SUMIFS('Sales Transactions Raw Data'!V:V,'Sales Transactions Raw Data'!S:S,"amazon-us",'Sales Transactions Raw Data'!B:B,"August",'Sales Transactions Raw Data'!A:A,2025,'Sales Transactions Raw Data'!J:J,"Finished Goods") -> 0 | F5: =SUMIFS('Sales Transactions Raw Data'!V:V,'Sales Transactions Raw Data'!S:S,"amazon-us",'Sales Transactions Raw Data'!B:B,"September",'Sales Transactions Raw Data'!A:A,2025,'Sales Transactions Raw Data'!J:J,"Finished Goods") -> 0 | G5: =SUMIFS('Sales Transactions Raw Data'!V:V,'Sales Transactions Raw Data'!S:S,"amazon-us",'Sales Transactions Raw Data'!B:B,"October",'Sales Transactions Raw Data'!A:A,2025,'Sales Transactions Raw Data'!J:J,"Finished Goods") -> 0 | H5: =SUMIFS('Sales Transactions Raw Data'!V:V,'Sales Transactions Raw Data'!S:S,"amazon-us",'Sales Transactions Raw Data'!B:B,"November",'Sales Transactions Raw Data'!A:A,2025,'Sales Transactions Raw Data'!J:J,"Finished Goods") -> 0 | I5: =SUMIFS('Sales Transactions Raw Data'!V:V,'Sales Transactions Raw Data'!R:R,"Amazon.com",'Sales Transactions Raw Data'!B:B,"January",'Sales Transactions Raw Data'!A:A,2026,'Sales Transactions Raw Data'!J:J,"Finished Goods") -> 0 | J5: =SUMIFS('Sales Transactions Raw Data'!V:V,'Sales Transactions Raw Data'!R:R,"Amazon.com",'Sales Transactions Raw Data'!B:B,"February",'Sales Transactions Raw Data'!A:A,2026,'Sales Transactions Raw Data'!J:J,"Finished Goods") -> 0 | K5: =SUMIFS('Sales Transactions Raw Data'!V:V,'Sales Transactions Raw Data'!R:R,"Amazon.com",'Sales Transactions Raw Data'!B:B,"March",'Sales Transactions Raw Data'!A:A,2026,'Sales Transactions Raw Data'!J:J,"Finished Goods") -> 0 | L5: =SUM(B5:K5) -> 0
A6: Shopify Web (D2C) | B6: =SUMIFS('Sales Transactions Raw Data'!V:V,'Sales Transactions Raw Data'!S:S,"Shopify web",'Sales Transactions Raw Data'!B:B,"March",'Sales Transactions Raw Data'!A:A,2025,'Sales Transactions Raw Data'!J:J,"Finished Goods") -> 0 | C6: =SUMIFS('Sales Transactions Raw Data'!V:V,'Sales Transactions Raw Data'!S:S,"Shopify web",'Sales Transactions Raw Data'!B:B,"March",'Sales Transactions Raw Data'!A:A,2025,'Sales Transactions Raw Data'!J:J,"Finished Goods") -> 0 | D6: =SUMIFS('Sales Transactions Raw Data'!V:V,'Sales Transactions Raw Data'!S:S,"Shopify web",'Sales Transactions Raw Data'!B:B,"July",'Sales Transactions Raw Data'!A:A,2025,'Sales Transactions Raw Data'!J:J,"Finished Goods") -> 0 | E6: =SUMIFS('Sales Transactions Raw Data'!V:V,'Sales Transactions Raw Data'!S:S,"Shopify web",'Sales Transactions Raw Data'!B:B,"August",'Sales Transactions Raw Data'!A:A,2025,'Sales Transactions Raw Data'!J:J,"Finished Goods") -> 0 | F6: =SUMIFS('Sales Transactions Raw Data'!V:V,'Sales Transactions Raw Data'!S:S,"Shopify web",'Sales Transactions Raw Data'!B:B,"September",'Sales Transactions Raw Data'!A:A,2025,'Sales Transactions Raw Data'!J:J,"Finished Goods") -> 0 | G6: =SUMIFS('Sales Transactions Raw Data'!V:V,'Sales Transactions Raw Data'!S:S,"Shopify web",'Sales Transactions Raw Data'!B:B,"October",'Sales Transactions Raw Data'!A:A,2025,'Sales Transactions Raw Data'!J:J,"Finished Goods") -> 0 | H6: =SUMIFS('Sales Transactions Raw Data'!V:V,'Sales Transactions Raw Data'!S:S,"Shopify web",'Sales Transactions Raw Data'!B:B,"November",'Sales Transactions Raw Data'!A:A,2025,'Sales Transactions Raw Data'!J:J,"Finished Goods") -> 0 | I6: =SUMIFS('Sales Transactions Raw Data'!V:V,'Sales Transactions Raw Data'!S:S,"Shopify web",'Sales Transactions Raw Data'!B:B,"January",'Sales Transactions Raw Data'!A:A,2026,'Sales Transactions Raw Data'!J:J,"Finished Goods") -> 0 | J6: =SUMIFS('Sales Transactions Raw Data'!V:V,'Sales Transactions Raw Data'!S:S,"Shopify web",'Sales Transactions Raw Data'!B:B,"February",'Sales Transactions Raw Data'!A:A,2026,'Sales Transactions Raw Data'!J:J,"Finished Goods") -> 0 | K6: =SUMIFS('Sales Transactions Raw Data'!V:V,'Sales Transactions Raw Data'!S:S,"Shopify web",'Sales Transactions Raw Data'!B:B,"March",'Sales Transactions Raw Data'!A:A,2026,'Sales Transactions Raw Data'!J:J,"Finished Goods") -> 0 | L6: =SUM(B6:K6) -> 0
A7: Shopify POS (In-store) | B7: =SUMIFS('Sales Transactions Raw Data'!V:V,'Sales Transactions Raw Data'!S:S,"tiktok",'Sales Transactions Raw Data'!B:B,"March",'Sales Transactions Raw Data'!A:A,2025,'Sales Transactions Raw Data'!J:J,"Finished Goods") -> 0 | C7: =SUMIFS('Sales Transactions Raw Data'!V:V,'Sales Transactions Raw Data'!S:S,"Shopify POS",'Sales Transactions Raw Data'!B:B,"March",'Sales Transactions Raw Data'!A:A,2025,'Sales Transactions Raw Data'!J:J,"Finished Goods") -> 0 | D7: =SUMIFS('Sales Transactions Raw Data'!V:V,'Sales Transactions Raw Data'!S:S,"Shopify POS",'Sales Transactions Raw Data'!B:B,"July",'Sales Transactions Raw Data'!A:A,2025,'Sales Transactions Raw Data'!J:J,"Finished Goods") -> 0 | E7: =SUMIFS('Sales Transactions Raw Data'!V:V,'Sales Transactions Raw Data'!S:S,"Shopify POS",'Sales Transactions Raw Data'!B:B,"August",'Sales Transactions Raw Data'!A:A,2025,'Sales Transactions Raw Data'!J:J,"Finished Goods") -> 0 | F7: =SUMIFS('Sales Transactions Raw Data'!V:V,'Sales Transactions Raw Data'!S:S,"Shopify POS",'Sales Transactions Raw Data'!B:B,"September",'Sales Transactions Raw Data'!A:A,2025,'Sales Transactions Raw Data'!J:J,"Finished Goods") -> 0 | G7: =SUMIFS('Sales Transactions Raw Data'!V:V,'Sales Transactions Raw Data'!S:S,"Shopify POS",'Sales Transactions Raw Data'!B:B,"October",'Sales Transactions Raw Data'!A:A,2025,'Sales Transactions Raw Data'!J:J,"Finished Goods") -> 0 | H7: =SUMIFS('Sales Transactions Raw Data'!V:V,'Sales Transactions Raw Data'!S:S,"Shopify POS",'Sales Transactions Raw Data'!B:B,"November",'Sales Transactions Raw Data'!A:A,2025,'Sales Transactions Raw Data'!J:J,"Finished Goods") -> 0 | I7: =SUMIFS('Sales Transactions Raw Data'!V:V,'Sales Transactions Raw Data'!S:S,"tiktok",'Sales Transactions Raw Data'!B:B,"January",'Sales Transactions Raw Data'!A:A,2026,'Sales Transactions Raw Data'!J:J,"Finished Goods") -> 0 | J7: =SUMIFS('Sales Transactions Raw Data'!V:V,'Sales Transactions Raw Data'!S:S,"tiktok",'Sales Transactions Raw Data'!B:B,"February",'Sales Transactions Raw Data'!A:A,2026,'Sales Transactions Raw Data'!J:J,"Finished Goods") -> 0 | K7: =SUMIFS('Sales Transactions Raw Data'!V:V,'Sales Transactions Raw Data'!S:S,"tiktok",'Sales Transactions Raw Data'!B:B,"March",'Sales Transactions Raw Data'!A:A,2026,'Sales Transactions Raw Data'!J:J,"Finished Goods") -> 0 | L7: =SUM(B7:K7) -> 0
A8: Shopify Admin (Samples/Manual) | B8: =SUMIFS('Sales Transactions Raw Data'!V:V,'Sales Transactions Raw Data'!S:S,"296827748353",'Sales Transactions Raw Data'!B:B,"March",'Sales Transactions Raw Data'!A:A,2025,'Sales Transactions Raw Data'!J:J,"Finished Goods") -> 0 | C8: =SUMIFS('Sales Transactions Raw Data'!V:V,'Sales Transactions Raw Data'!S:S,"Shopify admin",'Sales Transactions Raw Data'!B:B,"March",'Sales Transactions Raw Data'!A:A,2025,'Sales Transactions Raw Data'!J:J,"Finished Goods") -> 0 | D8: =SUMIFS('Sales Transactions Raw Data'!V:V,'Sales Transactions Raw Data'!S:S,"Shopify admin",'Sales Transactions Raw Data'!B:B,"July",'Sales Transactions Raw Data'!A:A,2025,'Sales Transactions Raw Data'!J:J,"Finished Goods") -> 0 | E8: =SUMIFS('Sales Transactions Raw Data'!V:V,'Sales Transactions Raw Data'!S:S,"Shopify admin",'Sales Transactions Raw Data'!B:B,"August",'Sales Transactions Raw Data'!A:A,2025,'Sales Transactions Raw Data'!J:J,"Finished Goods") -> 0 | F8: =SUMIFS('Sales Transactions Raw Data'!V:V,'Sales Transactions Raw Data'!S:S,"Shopify admin",'Sales Transactions Raw Data'!B:B,"September",'Sales Transactions Raw Data'!A:A,2025,'Sales Transactions Raw Data'!J:J,"Finished Goods") -> 0 | G8: =SUMIFS('Sales Transactions Raw Data'!V:V,'Sales Transactions Raw Data'!S:S,"Shopify admin",'Sales Transactions Raw Data'!B:B,"October",'Sales Transactions Raw Data'!A:A,2025,'Sales Transactions Raw Data'!J:J,"Finished Goods") -> 0 | H8: =SUMIFS('Sales Transactions Raw Data'!V:V,'Sales Transactions Raw Data'!S:S,"Shopify admin",'Sales Transactions Raw Data'!B:B,"November",'Sales Transactions Raw Data'!A:A,2025,'Sales Transactions Raw Data'!J:J,"Finished Goods") -> 0 | I8: =SUMIFS('Sales Transactions Raw Data'!V:V,'Sales Transactions Raw Data'!S:S,"296827748353",'Sales Transactions Raw Data'!B:B,"January",'Sales Transactions Raw Data'!A:A,2026,'Sales Transactions Raw Data'!J:J,"Finished Goods") -> 0 | J8: =SUMIFS('Sales Transactions Raw Data'!V:V,'Sales Transactions Raw Data'!S:S,"296827748353",'Sales Transactions Raw Data'!B:B,"February",'Sales Transactions Raw Data'!A:A,2026,'Sales Transactions Raw Data'!J:J,"Finished Goods") -> 0 | K8: =SUMIFS('Sales Transactions Raw Data'!V:V,'Sales Transactions Raw Data'!S:S,"296827748353",'Sales Transactions Raw Data'!B:B,"March",'Sales Transactions Raw Data'!A:A,2026,'Sales Transactions Raw Data'!J:J,"Finished Goods") -> 0 | L8: =SUM(B8:K8) -> 0
A9: Subscriptions (contract) | B9: =SUMIFS('Sales Transactions Raw Data'!V:V,'Sales Transactions Raw Data'!S:S,"Shopify POS",'Sales Transactions Raw Data'!B:B,"March",'Sales Transactions Raw Data'!A:A,2025) -> 0 | C9: =SUMIFS('Sales Transactions Raw Data'!V:V,'Sales Transactions Raw Data'!S:S,"subscription_contract",'Sales Transactions Raw Data'!B:B,"March",'Sales Transactions Raw Data'!A:A,2025,'Sales Transactions Raw Data'!J:J,"Finished Goods") -> 0 | D9: =SUMIFS('Sales Transactions Raw Data'!V:V,'Sales Transactions Raw Data'!S:S,"subscription_contract",'Sales Transactions Raw Data'!B:B,"July",'Sales Transactions Raw Data'!A:A,2025,'Sales Transactions Raw Data'!J:J,"Finished Goods") -> 0 | E9: =SUMIFS('Sales Transactions Raw Data'!V:V,'Sales Transactions Raw Data'!S:S,"subscription_contract",'Sales Transactions Raw Data'!B:B,"August",'Sales Transactions Raw Data'!A:A,2025,'Sales Transactions Raw Data'!J:J,"Finished Goods") -> 0 | F9: =SUMIFS('Sales Transactions Raw Data'!V:V,'Sales Transactions Raw Data'!S:S,"subscription_contract",'Sales Transactions Raw Data'!B:B,"September",'Sales Transactions Raw Data'!A:A,2025,'Sales Transactions Raw Data'!J:J,"Finished Goods") -> 0 | G9: =SUMIFS('Sales Transactions Raw Data'!V:V,'Sales Transactions Raw Data'!S:S,"subscription_contract",'Sales Transactions Raw Data'!B:B,"October",'Sales Transactions Raw Data'!A:A,2025,'Sales Transactions Raw Data'!J:J,"Finished Goods") -> 0 | H9: =SUMIFS('Sales Transactions Raw Data'!V:V,'Sales Transactions Raw Data'!S:S,"subscription_contract",'Sales Transactions Raw Data'!B:B,"November",'Sales Transactions Raw Data'!A:A,2025,'Sales Transactions Raw Data'!J:J,"Finished Goods") -> 0 | I9: =SUMIFS('Sales Transactions Raw Data'!V:V,'Sales Transactions Raw Data'!S:S,"Shopify POS",'Sales Transactions Raw Data'!B:B,"January",'Sales Transactions Raw Data'!A:A,2026) -> 0 | J9: =SUMIFS('Sales Transactions Raw Data'!V:V,'Sales Transactions Raw Data'!S:S,"Shopify POS",'Sales Transactions Raw Data'!B:B,"February",'Sales Transactions Raw Data'!A:A,2026) -> 0 | K9: =SUMIFS('Sales Transactions Raw Data'!V:V,'Sales Transactions Raw Data'!S:S,"Shopify POS",'Sales Transactions Raw Data'!B:B,"March",'Sales Transactions Raw Data'!A:A,2026) -> 0 | L9: =SUM(B9:K9) -> 0
A10: Subscriptions (checkout) | B10: =SUMIFS('Sales Transactions Raw Data'!V:V,'Sales Transactions Raw Data'!S:S,"subscription_contract",'Sales Transactions Raw Data'!B:B,"March",'Sales Transactions Raw Data'!A:A,2025,'Sales Transactions Raw Data'!J:J,"Finished Goods")+SUMIFS('Sales Transactions Raw Data'!V:V,'Sales Transactions Raw Data'!S:S,"subscription_contract_checkout_one",'Sales Transactions Raw Data'!B:B,"March",'Sales Transactions Raw Data'!A:A,2025,'Sales Transactions Raw Data'!J:J,"Finished Goods") -> 0 | C10: =SUMIFS('Sales Transactions Raw Data'!V:V,'Sales Transactions Raw Data'!S:S,"subscription_contract_checkout_one",'Sales Transactions Raw Data'!B:B,"March",'Sales Transactions Raw Data'!A:A,2025,'Sales Transactions Raw Data'!J:J,"Finished Goods") -> 0 | D10: =SUMIFS('Sales Transactions Raw Data'!V:V,'Sales Transactions Raw Data'!S:S,"subscription_contract_checkout_one",'Sales Transactions Raw Data'!B:B,"July",'Sales Transactions Raw Data'!A:A,2025,'Sales Transactions Raw Data'!J:J,"Finished Goods") -> 0 | E10: =SUMIFS('Sales Transactions Raw Data'!V:V,'Sales Transactions Raw Data'!S:S,"subscription_contract_checkout_one",'Sales Transactions Raw Data'!B:B,"August",'Sales Transactions Raw Data'!A:A,2025,'Sales Transactions Raw Data'!J:J,"Finished Goods") -> 0 | F10: =SUMIFS('Sales Transactions Raw Data'!V:V,'Sales Transactions Raw Data'!S:S,"subscription_contract_checkout_one",'Sales Transactions Raw Data'!B:B,"September",'Sales Transactions Raw Data'!A:A,2025,'Sales Transactions Raw Data'!J:J,"Finished Goods") -> 0 | G10: =SUMIFS('Sales Transactions Raw Data'!V:V,'Sales Transactions Raw Data'!S:S,"subscription_contract_checkout_one",'Sales Transactions Raw Data'!B:B,"October",'Sales Transactions Raw Data'!A:A,2025,'Sales Transactions Raw Data'!J:J,"Finished Goods") -> 0 | H10: =SUMIFS('Sales Transactions Raw Data'!V:V,'Sales Transactions Raw Data'!S:S,"subscription_contract_checkout_one",'Sales Transactions Raw Data'!B:B,"November",'Sales Transactions Raw Data'!A:A,2025,'Sales Transactions Raw Data'!J:J,"Finished Goods") -> 0 | I10: =SUMIFS('Sales Transactions Raw Data'!V:V,'Sales Transactions Raw Data'!S:S,"subscription_contract",'Sales Transactions Raw Data'!B:B,"January",'Sales Transactions Raw Data'!A:A,2026,'Sales Transactions Raw Data'!J:J,"Finished Goods")+SUMIFS('Sales Transactions Raw Data'!V:V,'Sales Transactions Raw Data'!S:S,"subscription_contract_checkout_one",'Sales Transactions Raw Data'!B:B,"January",'Sales Transactions Raw Data'!A:A,2026,'Sales Transactions Raw Data'!J:J,"Finished Goods") -> 0 | J10: =SUMIFS('Sales Transactions Raw Data'!V:V,'Sales Transactions Raw Data'!S:S,"subscription_contract",'Sales Transactions Raw Data'!B:B,"February",'Sales Transactions Raw Data'!A:A,2026,'Sales Transactions Raw Data'!J:J,"Finished Goods")+SUMIFS('Sales Transactions Raw Data'!V:V,'Sales Transactions Raw Data'!S:S,"subscription_contract_checkout_one",'Sales Transactions Raw Data'!B:B,"February",'Sales Transactions Raw Data'!A:A,2026,'Sales Transactions Raw Data'!J:J,"Finished Goods") -> 0 | K10: =SUMIFS('Sales Transactions Raw Data'!V:V,'Sales Transactions Raw Data'!S:S,"subscription_contract",'Sales Transactions Raw Data'!B:B,"March",'Sales Transactions Raw Data'!A:A,2026,'Sales Transactions Raw Data'!J:J,"Finished Goods")+SUMIFS('Sales Transactions Raw Data'!V:V,'Sales Transactions Raw Data'!S:S,"subscription_contract_checkout_one",'Sales Transactions Raw Data'!B:B,"March",'Sales Transactions Raw Data'!A:A,2026,'Sales Transactions Raw Data'!J:J,"Finished Goods") -> 0 | L10: =SUM(B10:K10) -> 0
A11: Wholesale / Distrib (296827748353) | B11: =SUMIFS('Sales Transactions Raw Data'!V:V,'Sales Transactions Raw Data'!S:S,"Shopify admin",'Sales Transactions Raw Data'!B:B,"March",'Sales Transactions Raw Data'!A:A,2025,'Sales Transactions Raw Data'!J:J,"Finished Goods") -> 0 | C11: =SUMIFS('Sales Transactions Raw Data'!V:V,'Sales Transactions Raw Data'!S:S,"296827748353",'Sales Transactions Raw Data'!B:B,"March",'Sales Transactions Raw Data'!A:A,2025,'Sales Transactions Raw Data'!J:J,"Finished Goods") -> 0 | D11: =SUMIFS('Sales Transactions Raw Data'!V:V,'Sales Transactions Raw Data'!S:S,"296827748353",'Sales Transactions Raw Data'!B:B,"July",'Sales Transactions Raw Data'!A:A,2025,'Sales Transactions Raw Data'!J:J,"Finished Goods") -> 0 | E11: =SUMIFS('Sales Transactions Raw Data'!V:V,'Sales Transactions Raw Data'!S:S,"296827748353",'Sales Transactions Raw Data'!B:B,"August",'Sales Transactions Raw Data'!A:A,2025,'Sales Transactions Raw Data'!J:J,"Finished Goods") -> 0 | F11: =SUMIFS('Sales Transactions Raw Data'!V:V,'Sales Transactions Raw Data'!S:S,"296827748353",'Sales Transactions Raw Data'!B:B,"September",'Sales Transactions Raw Data'!A:A,2025,'Sales Transactions Raw Data'!J:J,"Finished Goods") -> 0 | G11: =SUMIFS('Sales Transactions Raw Data'!V:V,'Sales Transactions Raw Data'!S:S,"296827748353",'Sales Transactions Raw Data'!B:B,"October",'Sales Transactions Raw Data'!A:A,2025,'Sales Transactions Raw Data'!J:J,"Finished Goods") -> 0 | H11: =SUMIFS('Sales Transactions Raw Data'!V:V,'Sales Transactions Raw Data'!S:S,"296827748353",'Sales Transactions Raw Data'!B:B,"November",'Sales Transactions Raw Data'!A:A,2025,'Sales Transactions Raw Data'!J:J,"Finished Goods") -> 0 | I11: =SUMIFS('Sales Transactions Raw Data'!V:V,'Sales Transactions Raw Data'!S:S,"Shopify admin",'Sales Transactions Raw Data'!B:B,"January",'Sales Transactions Raw Data'!A:A,2026,'Sales Transactions Raw Data'!J:J,"Finished Goods") -> 0 | J11: =SUMIFS('Sales Transactions Raw Data'!V:V,'Sales Transactions Raw Data'!S:S,"Shopify admin",'Sales Transactions Raw Data'!B:B,"February",'Sales Transactions Raw Data'!A:A,2026,'Sales Transactions Raw Data'!J:J,"Finished Goods") -> 0 | K11: =SUMIFS('Sales Transactions Raw Data'!V:V,'Sales Transactions Raw Data'!S:S,"Shopify admin",'Sales Transactions Raw Data'!B:B,"March",'Sales Transactions Raw Data'!A:A,2026,'Sales Transactions Raw Data'!J:J,"Finished Goods") -> 0 | L11: =SUM(B11:K11) -> 0
A12: Faire (Wholesale Mkt) | C12: =SUMIFS('Sales Transactions Raw Data'!V:V,'Sales Transactions Raw Data'!S:S,"faire",'Sales Transactions Raw Data'!B:B,"March",'Sales Transactions Raw Data'!A:A,2025,'Sales Transactions Raw Data'!J:J,"Finished Goods") -> 0 | D12: =SUMIFS('Sales Transactions Raw Data'!V:V,'Sales Transactions Raw Data'!S:S,"faire",'Sales Transactions Raw Data'!B:B,"July",'Sales Transactions Raw Data'!A:A,2025,'Sales Transactions Raw Data'!J:J,"Finished Goods") -> 0 | E12: =SUMIFS('Sales Transactions Raw Data'!V:V,'Sales Transactions Raw Data'!S:S,"faire",'Sales Transactions Raw Data'!B:B,"August",'Sales Transactions Raw Data'!A:A,2025,'Sales Transactions Raw Data'!J:J,"Finished Goods") -> 0 | F12: =SUMIFS('Sales Transactions Raw Data'!V:V,'Sales Transactions Raw Data'!S:S,"faire",'Sales Transactions Raw Data'!B:B,"September",'Sales Transactions Raw Data'!A:A,2025,'Sales Transactions Raw Data'!J:J,"Finished Goods") -> 0 | G12: =SUMIFS('Sales Transactions Raw Data'!V:V,'Sales Transactions Raw Data'!S:S,"faire",'Sales Transactions Raw Data'!B:B,"October",'Sales Transactions Raw Data'!A:A,2025,'Sales Transactions Raw Data'!J:J,"Finished Goods") -> 0 | H12: =SUMIFS('Sales Transactions Raw Data'!V:V,'Sales Transactions Raw Data'!S:S,"faire",'Sales Transactions Raw Data'!B:B,"November",'Sales Transactions Raw Data'!A:A,2025,'Sales Transactions Raw Data'!J:J,"Finished Goods") -> 0
A13: TikTok Shop | B13: =SUM(B4:B11) -> 0 | C13: =SUMIFS('Sales Transactions Raw Data'!V:V,'Sales Transactions Raw Data'!S:S,"tiktok",'Sales Transactions Raw Data'!B:B,"March",'Sales Transactions Raw Data'!A:A,2025,'Sales Transactions Raw Data'!J:J,"Finished Goods") -> 0 | D13: =SUMIFS('Sales Transactions Raw Data'!V:V,'Sales Transactions Raw Data'!S:S,"tiktok",'Sales Transactions Raw Data'!B:B,"July",'Sales Transactions Raw Data'!A:A,2025,'Sales Transactions Raw Data'!J:J,"Finished Goods") -> 0 | E13: =SUMIFS('Sales Transactions Raw Data'!V:V,'Sales Transactions Raw Data'!S:S,"tiktok",'Sales Transactions Raw Data'!B:B,"August",'Sales Transactions Raw Data'!A:A,2025,'Sales Transactions Raw Data'!J:J,"Finished Goods") -> 0 | F13: =SUMIFS('Sales Transactions Raw Data'!V:V,'Sales Transactions Raw Data'!S:S,"tiktok",'Sales Transactions Raw Data'!B:B,"September",'Sales Transactions Raw Data'!A:A,2025,'Sales Transactions Raw Data'!J:J,"Finished Goods") -> 0 | G13: =SUMIFS('Sales Transactions Raw Data'!V:V,'Sales Transactions Raw Data'!S:S,"tiktok",'Sales Transactions Raw Data'!B:B,"October",'Sales Transactions Raw Data'!A:A,2025,'Sales Transactions Raw Data'!J:J,"Finished Goods") -> 0 | H13: =SUMIFS('Sales Transactions Raw Data'!V:V,'Sales Transactions Raw Data'!S:S,"tiktok",'Sales Transactions Raw Data'!B:B,"November",'Sales Transactions Raw Data'!A:A,2025,'Sales Transactions Raw Data'!J:J,"Finished Goods") -> 0 | I13: =SUM(I4:I11) -> 0 | J13: =SUM(J4:J11) -> 0 | K13: =SUM(K4:K11) -> 0 | L13: =SUM(L4:L11) -> 0
A14: Channel 4901177 | C14: =SUMIFS('Sales Transactions Raw Data'!V:V,'Sales Transactions Raw Data'!S:S,"4901177",'Sales Transactions Raw Data'!B:B,"March",'Sales Transactions Raw Data'!A:A,2025,'Sales Transactions Raw Data'!J:J,"Finished Goods") -> 0 | D14: =SUMIFS('Sales Transactions Raw Data'!V:V,'Sales Transactions Raw Data'!S:S,"4901177",'Sales Transactions Raw Data'!B:B,"July",'Sales Transactions Raw Data'!A:A,2025,'Sales Transactions Raw Data'!J:J,"Finished Goods") -> 0 | E14: =SUMIFS('Sales Transactions Raw Data'!V:V,'Sales Transactions Raw Data'!S:S,"4901177",'Sales Transactions Raw Data'!B:B,"August",'Sales Transactions Raw Data'!A:A,2025,'Sales Transactions Raw Data'!J:J,"Finished Goods") -> 0 | F14: =SUMIFS('Sales Transactions Raw Data'!V:V,'Sales Transactions Raw Data'!S:S,"4901177",'Sales Transactions Raw Data'!B:B,"September",'Sales Transactions Raw Data'!A:A,2025,'Sales Transactions Raw Data'!J:J,"Finished Goods") -> 0 | G14: =SUMIFS('Sales Transactions Raw Data'!V:V,'Sales Transactions Raw Data'!S:S,"4901177",'Sales Transactions Raw Data'!B:B,"October",'Sales Transactions Raw Data'!A:A,2025,'Sales Transactions Raw Data'!J:J,"Finished Goods") -> 0 | H14: =SUMIFS('Sales Transactions Raw Data'!V:V,'Sales Transactions Raw Data'!S:S,"4901177",'Sales Transactions Raw Data'!B:B,"November",'Sales Transactions Raw Data'!A:A,2025,'Sales Transactions Raw Data'!J:J,"Finished Goods") -> 0
A15: Channel 3890849 | B15: - | C15: =SUMIFS('Sales Transactions Raw Data'!V:V,'Sales Transactions Raw Data'!S:S,"3890849",'Sales Transactions Raw Data'!B:B,"March",'Sales Transactions Raw Data'!A:A,2025,'Sales Transactions Raw Data'!J:J,"Finished Goods") -> 0 | D15: =SUMIFS('Sales Transactions Raw Data'!V:V,'Sales Transactions Raw Data'!S:S,"3890849",'Sales Transactions Raw Data'!B:B,"July",'Sales Transactions Raw Data'!A:A,2025,'Sales Transactions Raw Data'!J:J,"Finished Goods") -> 0 | E15: =SUMIFS('Sales Transactions Raw Data'!V:V,'Sales Transactions Raw Data'!S:S,"3890849",'Sales Transactions Raw Data'!B:B,"August",'Sales Transactions Raw Data'!A:A,2025,'Sales Transactions Raw Data'!J:J,"Finished Goods") -> 0 | F15: =SUMIFS('Sales Transactions Raw Data'!V:V,'Sales Transactions Raw Data'!S:S,"3890849",'Sales Transactions Raw Data'!B:B,"September",'Sales Transactions Raw Data'!A:A,2025,'Sales Transactions Raw Data'!J:J,"Finished Goods") -> 0 | G15: =SUMIFS('Sales Transactions Raw Data'!V:V,'Sales Transactions Raw Data'!S:S,"3890849",'Sales Transactions Raw Data'!B:B,"October",'Sales Transactions Raw Data'!A:A,2025,'Sales Transactions Raw Data'!J:J,"Finished Goods") -> 0 | H15: =SUMIFS('Sales Transactions Raw Data'!V:V,'Sales Transactions Raw Data'!S:S,"3890849",'Sales Transactions Raw Data'!B:B,"November",'Sales Transactions Raw Data'!A:A,2025,'Sales Transactions Raw Data'!J:J,"Finished Goods") -> 0 | I15: =IF(H13=0,"-",I13/H13-1) -> - | J15: =IF(I13=0,"-",J13/I13-1) -> - | K15: =IF(J13=0,"-",K13/J13-1) -> -
A16: Channel 2329312 | C16: =SUMIFS('Sales Transactions Raw Data'!V:V,'Sales Transactions Raw Data'!S:S,"2329312",'Sales Transactions Raw Data'!B:B,"March",'Sales Transactions Raw Data'!A:A,2025,'Sales Transactions Raw Data'!J:J,"Finished Goods") -> 0 | D16: =SUMIFS('Sales Transactions Raw Data'!V:V,'Sales Transactions Raw Data'!S:S,"2329312",'Sales Transactions Raw Data'!B:B,"July",'Sales Transactions Raw Data'!A:A,2025,'Sales Transactions Raw Data'!J:J,"Finished Goods") -> 0 | E16: =SUMIFS('Sales Transactions Raw Data'!V:V,'Sales Transactions Raw Data'!S:S,"2329312",'Sales Transactions Raw Data'!B:B,"August",'Sales Transactions Raw Data'!A:A,2025,'Sales Transactions Raw Data'!J:J,"Finished Goods") -> 0 | F16: =SUMIFS('Sales Transactions Raw Data'!V:V,'Sales Transactions Raw Data'!S:S,"2329312",'Sales Transactions Raw Data'!B:B,"September",'Sales Transactions Raw Data'!A:A,2025,'Sales Transactions Raw Data'!J:J,"Finished Goods") -> 0 | G16: =SUMIFS('Sales Transactions Raw Data'!V:V,'Sales Transactions Raw Data'!S:S,"2329312",'Sales Transactions Raw Data'!B:B,"October",'Sales Transactions Raw Data'!A:A,2025,'Sales Transactions Raw Data'!J:J,"Finished Goods") -> 0 | H16: =SUMIFS('Sales Transactions Raw Data'!V:V,'Sales Transactions Raw Data'!S:S,"2329312",'Sales Transactions Raw Data'!B:B,"November",'Sales Transactions Raw Data'!A:A,2025,'Sales Transactions Raw Data'!J:J,"Finished Goods") -> 0
A17: TOTAL REVENUE | B17: =SUMIFS('Sales Transactions Raw Data'!W:W,'Sales Transactions Raw Data'!B:B,"March",'Sales Transactions Raw Data'!A:A,2025,'Sales Transactions Raw Data'!J:J,"Finished Goods") -> 0 | C17: =SUM(C4:C16) -> 0 | D17: =SUM(D4:D16) -> 0 | E17: =SUM(E4:E16) -> 0 | F17: =SUM(F4:F16) -> 0 | G17: =SUM(G4:G16) -> 0 | H17: =SUM(H4:H16) -> 0 | I17: =SUMIFS('Sales Transactions Raw Data'!W:W,'Sales Transactions Raw Data'!B:B,"January",'Sales Transactions Raw Data'!A:A,2026,'Sales Transactions Raw Data'!J:J,"Finished Goods") -> 0 | J17: =SUMIFS('Sales Transactions Raw Data'!W:W,'Sales Transactions Raw Data'!B:B,"February",'Sales Transactions Raw Data'!A:A,2026,'Sales Transactions Raw Data'!J:J,"Finished Goods") -> 0 | K17: =SUMIFS('Sales Transactions Raw Data'!W:W,'Sales Transactions Raw Data'!B:B,"March",'Sales Transactions Raw Data'!A:A,2026,'Sales Transactions Raw Data'!J:J,"Finished Goods") -> 0 | L17: =SUM(B17:K17) -> 0
A18: GROSS PROFIT | B18: =B13-B17 -> 0 | C18: =C13-C17 -> 0 | D18: =D13-D17 -> 0 | E18: =E13-E17 -> 0 | F18: =F13-F17 -> 0 | G18: =G13-G17 -> 0 | H18: =H13-H17 -> 0 | I18: =I13-I17 -> 0 | ... L18: =L13-L17 -> 0
A19: COGS (All Finished Goods) | B19: =IF(B13=0,"-",B18/B13) -> - | C19: =SUMIFS('Sales Transactions Raw Data'!W:W,'Sales Transactions Raw Data'!B:B,"March",'Sales Transactions Raw Data'!A:A,2025,'Sales Transactions Raw Data'!J:J,"Finished Goods") -> 0 | D19: =SUMIFS('Sales Transactions Raw Data'!W:W,'Sales Transactions Raw Data'!B:B,"July",'Sales Transactions Raw Data'!A:A,2025,'Sales Transactions Raw Data'!J:J,"Finished Goods") -> 0 | E19: =SUMIFS('Sales Transactions Raw Data'!W:W,'Sales Transactions Raw Data'!B:B,"August",'Sales Transactions Raw Data'!A:A,2025,'Sales Transactions Raw Data'!J:J,"Finished Goods") -> 0 | F19: =SUMIFS('Sales Transactions Raw Data'!W:W,'Sales Transactions Raw Data'!B:B,"September",'Sales Transactions Raw Data'!A:A,2025,'Sales Transactions Raw Data'!J:J,"Finished Goods") -> 0 | G19: =SUMIFS('Sales Transactions Raw Data'!W:W,'Sales Transactions Raw Data'!B:B,"October",'Sales Transactions Raw Data'!A:A,2025,'Sales Transactions Raw Data'!J:J,"Finished Goods") -> 0 | H19: =SUMIFS('Sales Transactions Raw Data'!W:W,'Sales Transactions Raw Data'!B:B,"November",'Sales Transactions Raw Data'!A:A,2025,'Sales Transactions Raw Data'!J:J,"Finished Goods") -> 0 | I19: =IF(I13=0,"-",I18/I13) -> - | J19: =IF(J13=0,"-",J18/J13) -> - | K19: =IF(K13=0,"-",K18/K13) -> - | L19: =IF(L13=0,"-",L18/L13) -> -
A20: Gross Profit | C20: =C17-C19 -> 0 | D20: =D17-D19 -> 0 | E20: =E17-E19 -> 0 | F20: =F17-F19 -> 0 | G20: =G17-G19 -> 0 | H20: =H17-H19 -> 0
A21: Gross Margin % | C21: =IF(C17=0,"-",C20/C17) -> - | D21: =IF(D17=0,"-",D20/D17) -> - | E21: =IF(E17=0,"-",E20/E17) -> - | F21: =IF(F17=0,"-",F20/F17) -> - | G21: =IF(G17=0,"-",G20/G17) -> - | H21: =IF(H17=0,"-",H20/H17) -> -
A22: MoM Revenue Growth | C22: — | D22: =IF(C17=0,"-",D17/C17-1) -> - | E22: =IF(D17=0,"-",E17/D17-1) -> - | F22: =IF(E17=0,"-",F17/E17-1) -> - | G22: =IF(F17=0,"-",G17/F17-1) -> - | H22: =IF(G17=0,"-",H17/G17-1) -> -

Sheet Product Margin Analysis
A1: Product Margin Analysis — by Product Attributes
A2: Filtered to Finished Goods only (excludes Service items like Shipping, Discounts)
A4: BY PRODUCT (SKU) | B4: Units Sold | C4: Revenue | D4: COGS | E4: Gross Profit | F4: GM% | G4: Avg Sell Price | H4: Avg COGS/Unit
A5: 16oz Variety 12pk | B5: =SUMIFS('Sales Transactions Raw Data'!T:T,'Sales Transactions Raw Data'!G:G,"Ola-Mate-VP1-16oz-12pk",'Sales Transactions Raw Data'!J:J,"Finished Goods") -> 0 | C5: =SUMIFS('Sales Transactions Raw Data'!V:V,'Sales Transactions Raw Data'!G:G,"Ola-Mate-VP1-16oz-12pk",'Sales Transactions Raw Data'!J:J,"Finished Goods") -> 0 | D5: =SUMIFS('Sales Transactions Raw Data'!W:W,'Sales Transactions Raw Data'!G:G,"Ola-Mate-VP1-16oz-12pk",'Sales Transactions Raw Data'!J:J,"Finished Goods") -> 0 | E5: =C5-D5 -> 0 | F5: =IF(C5=0,"-",E5/C5) -> - | G5: =IF(B5=0,"-",C5/B5) -> - | H5: =IF(B5=0,"-",D5/B5) -> -
A6: 16oz Berry Coconut 12pk | B6: =SUMIFS('Sales Transactions Raw Data'!T:T,'Sales Transactions Raw Data'!G:G,"Ola-Mate-BC-16oz-12PK",'Sales Transactions Raw Data'!J:J,"Finished Goods") -> 0 | C6: =SUMIFS('Sales Transactions Raw Data'!V:V,'Sales Transactions Raw Data'!G:G,"Ola-Mate-BC-16oz-12PK",'Sales Transactions Raw Data'!J:J,"Finished Goods") -> 0 | D6: =SUMIFS('Sales Transactions Raw Data'!W:W,'Sales Transactions Raw Data'!G:G,"Ola-Mate-BC-16oz-12PK",'Sales Transactions Raw Data'!J:J,"Finished Goods") -> 0 | E6: =C6-D6 -> 0 | F6: =IF(C6=0,"-",E6/C6) -> - | G6: =IF(B6=0,"-",C6/B6) -> - | H6: =IF(B6=0,"-",D6/B6) -> -
A7: 16oz Raspberry 12pk | B7: =SUMIFS('Sales Transactions Raw Data'!T:T,'Sales Transactions Raw Data'!G:G,"Ola-Mate-R-16oz-12pk",'Sales Transactions Raw Data'!J:J,"Finished Goods") -> 0 | C7: =SUMIFS('Sales Transactions Raw Data'!V:V,'Sales Transactions Raw Data'!G:G,"Ola-Mate-R-16oz-12pk",'Sales Transactions Raw Data'!J:J,"Finished Goods") -> 0 | D7: =SUMIFS('Sales Transactions Raw Data'!W:W,'Sales Transactions Raw Data'!G:G,"Ola-Mate-R-16oz-12pk",'Sales Transactions Raw Data'!J:J,"Finished Goods") -> 0 | E7: =C7-D7 -> 0 | F7: =IF(C7=0,"-",E7/C7) -> - | G7: =IF(B7=0,"-",C7/B7) -> - | H7: =IF(B7=0,"-",D7/B7) -> -
A8: 16oz Grapefruit Ginger 12pk | B8: =SUMIFS('Sales Transactions Raw Data'!T:T,'Sales Transactions Raw Data'!G:G,"Ola-Mate-GG-16oz-12pk",'Sales Transactions Raw Data'!J:J,"Finished Goods") -> 0 | C8: =SUMIFS('Sales Transactions Raw Data'!V:V,'Sales Transactions Raw Data'!G:G,"Ola-Mate-GG-16oz-12pk",'Sales Transactions Raw Data'!J:J,"Finished Goods") -> 0 | D8: =SUMIFS('Sales Transactions Raw Data'!W:W,'Sales Transactions Raw Data'!G:G,"Ola-Mate-GG-16oz-12pk",'Sales Transactions Raw Data'!J:J,"Finished Goods") -> 0 | E8: =C8-D8 -> 0 | F8: =IF(C8=0,"-",E8/C8) -> - | G8: =IF(B8=0,"-",C8/B8) -> - | H8: =IF(B8=0,"-",D8/B8) -> -
A9: 16oz Starter 4pk | B9: =SUMIFS('Sales Transactions Raw Data'!T:T,'Sales Transactions Raw Data'!G:G,"Ola-Mate-SP1-16oz-4pk",'Sales Transactions Raw Data'!J:J,"Finished Goods") -> 0 | C9: =SUMIFS('Sales Transactions Raw Data'!V:V,'Sales Transactions Raw Data'!G:G,"Ola-Mate-SP1-16oz-4pk",'Sales Transactions Raw Data'!J:J,"Finished Goods") -> 0 | D9: =SUMIFS('Sales Transactions Raw Data'!W:W,'Sales Transactions Raw Data'!G:G,"Ola-Mate-SP1-16oz-4pk",'Sales Transactions Raw Data'!J:J,"Finished Goods") -> 0 | E9: =C9-D9 -> 0 | F9: =IF(C9=0,"-",E9/C9) -> - | G9: =IF(B9=0,"-",C9/B9) -> - | H9: =IF(B9=0,"-",D9/B9) -> -
A10: 1can (BC/GG/R) - loose | B10: =SUMIFS('Sales Transactions Raw Data'!T:T,'Sales Transactions Raw Data'!G:G,"Ola-Mate-BC-16oz-1can",'Sales Transactions Raw Data'!J:J,"Finished Goods")+SUMIFS('Sales Transactions Raw Data'!T:T,'Sales Transactions Raw Data'!G:G,"Ola-Mate-GG-16oz-1can",'Sales Transactions Raw Data'!J:J,"Finished Goods")+SUMIFS('Sales Transactions Raw Data'!T:T,'Sales Transactions Raw Data'!G:G,"Ola-Mate-R-16oz-1can",'Sales Transactions Raw Data'!J:J,"Finished Goods") -> 0 | C10: =SUMIFS('Sales Transactions Raw Data'!V:V,'Sales Transactions Raw Data'!G:G,"Ola-Mate-BC-16oz-1can",'Sales Transactions Raw Data'!J:J,"Finished Goods")+SUMIFS('Sales Transactions Raw Data'!V:V,'Sales Transactions Raw Data'!G:G,"Ola-Mate-GG-16oz-1can",'Sales Transactions Raw Data'!J:J,"Finished Goods")+SUMIFS('Sales Transactions Raw Data'!V:V,'Sales Transactions Raw Data'!G:G,"Ola-Mate-R-16oz-1can",'Sales Transactions Raw Data'!J:J,"Finished Goods") -> 0 | D10: =SUMIFS('Sales Transactions Raw Data'!W:W,'Sales Transactions Raw Data'!G:G,"Ola-Mate-BC-16oz-1can",'Sales Transactions Raw Data'!J:J,"Finished Goods")+SUMIFS('Sales Transactions Raw Data'!W:W,'Sales Transactions Raw Data'!G:G,"Ola-Mate-GG-16oz-1can",'Sales Transactions Raw Data'!J:J,"Finished Goods")+SUMIFS('Sales Transactions Raw Data'!W:W,'Sales Transactions Raw Data'!G:G,"Ola-Mate-R-16oz-1can",'Sales Transactions Raw Data'!J:J,"Finished Goods") -> 0 | E10: =C10-D10 -> 0 | F10: =IF(C10=0,"-",E10/C10) -> - | G10: =IF(B10=0,"-",C10/B10) -> - | H10: =IF(B10=0,"-",D10/B10) -> -
A11: Powder Blends (new) | B11: =SUMIFS('Sales Transactions Raw Data'!T:T,'Sales Transactions Raw Data'!G:G,"Ola-Mate-POW-*",'Sales Transactions Raw Data'!J:J,"Finished Goods") -> 0 | C11: =SUMIFS('Sales Transactions Raw Data'!V:V,'Sales Transactions Raw Data'!G:G,"Ola-Mate-POW-*",'Sales Transactions Raw Data'!J:J,"Finished Goods") -> 0 | D11: =SUMIFS('Sales Transactions Raw Data'!W:W,'Sales Transactions Raw Data'!G:G,"Ola-Mate-POW-*",'Sales Transactions Raw Data'!J:J,"Finished Goods") -> 0 | E11: =C11-D11 -> 0 | F11: =IF(C11=0,"-",E11/C11) -> - | G11: =IF(B11=0,"-",C11/B11) -> - | H11: =IF(B11=0,"-",D11/B11) -> -
A12: TOTAL PRODUCTS | B12: =SUM(B5:B11) -> 0 | C12: =SUM(C5:C11) -> 0 | D12: =SUM(D5:D11) -> 0 | E12: =C12-D12 -> 0 | F12: =IF(C12=0,"-",E12/C12) -> - | G12: =IF(B12=0,"-",C12/B12) -> - | H12: =IF(B12=0,"-",D12/B12) -> -
A14: BY CATEGORY | B14: Units Sold | C14: Revenue | D14: COGS | E14: Gross Profit | F14: GM% | G14: Revenue % | H14: Avg Sell Price
A15: Finished Goods | B15: =SUMIFS('Sales Transactions Raw Data'!T:T,'Sales Transactions Raw Data'!J:J,"Finished Goods") -> 0 | C15: =SUMIFS('Sales Transactions Raw Data'!V:V,'Sales Transactions Raw Data'!J:J,"Finished Goods") -> 0 | D15: =SUMIFS('Sales Transactions Raw Data'!W:W,'Sales Transactions Raw Data'!J:J,"Finished Goods") -> 0 | E15: =C15-D15 -> 0 | F15: =IF(C15=0,"-",E15/C15) -> - | G15: =IF(C$17=0,"-",C15/C$17) -> - | H15: =IF(B15=0,"-",C15/B15) -> -
A16: Service (Shipping/Discounts/POS) | B16: =SUMIFS('Sales Transactions Raw Data'!T:T,'Sales Transactions Raw Data'!J:J,"Service") -> 0 | C16: =SUMIFS('Sales Transactions Raw Data'!V:V,'Sales Transactions Raw Data'!J:J,"Service") -> 0 | D16: =SUMIFS('Sales Transactions Raw Data'!W:W,'Sales Transactions Raw Data'!J:J,"Service") -> 0 | E16: =C16-D16 -> 0 | F16: =IF(C16=0,"-",E16/C16) -> - | G16: =IF(C$17=0,"-",C16/C$17) -> - | H16: =IF(B16=0,"-",C16/B16) -> -
A17: GRAND TOTAL | B17: =B15+B16 -> 0 | C17: =C15+C16 -> 0 | D17: =D15+D16 -> 0 | E17: =C17-D17 -> 0 | F17: =IF(C17=0,"-",E17/C17) -> - | G17: 1

Sheet COGS & Profitability by Channel
A1: COGS & Profitability by Product × Sales Channel
A2: Finished Goods only | All time periods combined
A4: REVENUE BY CHANNEL × PRODUCT | B4: Amazon | C4: Amazon Retail | D4: Shopify Web | E4: Shopify POS | F4: Shopify Admin | G4: Subs (contract) | H4: Subs (checkout) | I4: Wholesale 296... | J4: Faire | K4: TikTok | L4: Ch 4901177 | M4: Ch 3890849 | N4: Total
A5: 16oz Variety 12pk | B5: =SUMIFS('Sales Transactions Raw Data'!V:V,'Sales Transactions Raw Data'!G:G,"Ola-Mate-VP1-16oz-12pk",'Sales Transactions Raw Data'!S:S,"amazon",'Sales Transactions Raw Data'!J:J,"Finished Goods") -> 0 | C5: =SUMIFS('Sales Transactions Raw Data'!V:V,'Sales Transactions Raw Data'!G:G,"Ola-Mate-VP1-16oz-12pk",'Sales Transactions Raw Data'!S:S,"amazon-us",'Sales Transactions Raw Data'!J:J,"Finished Goods") -> 0 | D5: =SUMIFS('Sales Transactions Raw Data'!V:V,'Sales Transactions Raw Data'!G:G,"Ola-Mate-VP1-16oz-12pk",'Sales Transactions Raw Data'!S:S,"Shopify web",'Sales Transactions Raw Data'!J:J,"Finished Goods") -> 0 | E5: =SUMIFS('Sales Transactions Raw Data'!V:V,'Sales Transactions Raw Data'!G:G,"Ola-Mate-VP1-16oz-12pk",'Sales Transactions Raw Data'!S:S,"Shopify POS",'Sales Transactions Raw Data'!J:J,"Finished Goods") -> 0 | F5: =SUMIFS('Sales Transactions Raw Data'!V:V,'Sales Transactions Raw Data'!G:G,"Ola-Mate-VP1-16oz-12pk",'Sales Transactions Raw Data'!S:S,"Shopify admin",'Sales Transactions Raw Data'!J:J,"Finished Goods") -> 0 | G5: =SUMIFS('Sales Transactions Raw Data'!V:V,'Sales Transactions Raw Data'!G:G,"Ola-Mate-VP1-16oz-12pk",'Sales Transactions Raw Data'!S:S,"subscription_contract",'Sales Transactions Raw Data'!J:J,"Finished Goods") -> 0 | H5: =SUMIFS('Sales Transactions Raw Data'!V:V,'Sales Transactions Raw Data'!G:G,"Ola-Mate-VP1-16oz-12pk",'Sales Transactions Raw Data'!S:S,"subscription_contract_checkout_one",'Sales Transactions Raw Data'!J:J,"Finished Goods") -> 0 | I5: =SUMIFS('Sales Transactions Raw Data'!V:V,'Sales Transactions Raw Data'!G:G,"Ola-Mate-VP1-16oz-12pk",'Sales Transactions Raw Data'!S:S,"296827748353",'Sales Transactions Raw Data'!J:J,"Finished Goods") -> 0 | J5: =SUMIFS('Sales Transactions Raw Data'!V:V,'Sales Transactions Raw Data'!G:G,"Ola-Mate-VP1-16oz-12pk",'Sales Transactions Raw Data'!S:S,"faire",'Sales Transactions Raw Data'!J:J,"Finished Goods") -> 0 | K5: =SUMIFS('Sales Transactions Raw Data'!V:V,'Sales Transactions Raw Data'!G:G,"Ola-Mate-VP1-16oz-12pk",'Sales Transactions Raw Data'!S:S,"tiktok",'Sales Transactions Raw Data'!J:J,"Finished Goods") -> 0 | L5: =SUMIFS('Sales Transactions Raw Data'!V:V,'Sales Transactions Raw Data'!G:G,"Ola-Mate-VP1-16oz-12pk",'Sales Transactions Raw Data'!S:S,"4901177",'Sales Transactions Raw Data'!J:J,"Finished Goods") -> 0 | M5: =SUMIFS('Sales Transactions Raw Data'!V:V,'Sales Transactions Raw Data'!G:G,"Ola-Mate-VP1-16oz-12pk",'Sales Transactions Raw Data'!S:S,"3890849",'Sales Transactions Raw Data'!J:J,"Finished Goods") -> 0 | N5: =SUM(B5:M5) -> 0
A6: 16oz Berry Coconut 12pk | B6: =SUMIFS('Sales Transactions Raw Data'!V:V,'Sales Transactions Raw Data'!G:G,"Ola-Mate-BC-16oz-12PK",'Sales Transactions Raw Data'!S:S,"amazon",'Sales Transactions Raw Data'!J:J,"Finished Goods") -> 0 | C6: =SUMIFS('Sales Transactions Raw Data'!V:V,'Sales Transactions Raw Data'!G:G,"Ola-Mate-BC-16oz-12PK",'Sales Transactions Raw Data'!S:S,"amazon-us",'Sales Transactions Raw Data'!J:J,"Finished Goods") -> 0 | D6: =SUMIFS('Sales Transactions Raw Data'!V:V,'Sales Transactions Raw Data'!G:G,"Ola-Mate-BC-16oz-12PK",'Sales Transactions Raw Data'!S:S,"Shopify web",'Sales Transactions Raw Data'!J:J,"Finished Goods") -> 0 | E6: =SUMIFS('Sales Transactions Raw Data'!V:V,'Sales Transactions Raw Data'!G:G,"Ola-Mate-BC-16oz-12PK",'Sales Transactions Raw Data'!S:S,"Shopify POS",'Sales Transactions Raw Data'!J:J,"Finished Goods") -> 0 | F6: =SUMIFS('Sales Transactions Raw Data'!V:V,'Sales Transactions Raw Data'!G:G,"Ola-Mate-BC-16oz-12PK",'Sales Transactions Raw Data'!S:S,"Shopify admin",'Sales Transactions Raw Data'!J:J,"Finished Goods") -> 0 | G6: =SUMIFS('Sales Transactions Raw Data'!V:V,'Sales Transactions Raw Data'!G:G,"Ola-Mate-BC-16oz-12PK",'Sales Transactions Raw Data'!S:S,"subscription_contract",'Sales Transactions Raw Data'!J:J,"Finished Goods") -> 0 | H6: =SUMIFS('Sales Transactions Raw Data'!V:V,'Sales Transactions Raw Data'!G:G,"Ola-Mate-BC-16oz-12PK",'Sales Transactions Raw Data'!S:S,"subscription_contract_checkout_one",'Sales Transactions Raw Data'!J:J,"Finished Goods") -> 0 | I6: =SUMIFS('Sales Transactions Raw Data'!V:V,'Sales Transactions Raw Data'!G:G,"Ola-Mate-BC-16oz-12PK",'Sales Transactions Raw Data'!S:S,"296827748353",'Sales Transactions Raw Data'!J:J,"Finished Goods") -> 0 | J6: =SUMIFS('Sales Transactions Raw Data'!V:V,'Sales Transactions Raw Data'!G:G,"Ola-Mate-BC-16oz-12PK",'Sales Transactions Raw Data'!S:S,"faire",'Sales Transactions Raw Data'!J:J,"Finished Goods") -> 0 | K6: =SUMIFS('Sales Transactions Raw Data'!V:V,'Sales Transactions Raw Data'!G:G,"Ola-Mate-BC-16oz-12PK",'Sales Transactions Raw Data'!S:S,"tiktok",'Sales Transactions Raw Data'!J:J,"Finished Goods") -> 0 | L6: =SUMIFS('Sales Transactions Raw Data'!V:V,'Sales Transactions Raw Data'!G:G,"Ola-Mate-BC-16oz-12PK",'Sales Transactions Raw Data'!S:S,"4901177",'Sales Transactions Raw Data'!J:J,"Finished Goods") -> 0 | M6: =SUMIFS('Sales Transactions Raw Data'!V:V,'Sales Transactions Raw Data'!G:G,"Ola-Mate-BC-16oz-12PK",'Sales Transactions Raw Data'!S:S,"3890849",'Sales Transactions Raw Data'!J:J,"Finished Goods") -> 0 | N6: =SUM(B6:M6) -> 0
A7: 16oz Raspberry 12pk | B7: =SUMIFS('Sales Transactions Raw Data'!V:V,'Sales Transactions Raw Data'!G:G,"Ola-Mate-R-16oz-12pk",'Sales Transactions Raw Data'!S:S,"amazon",'Sales Transactions Raw Data'!J:J,"Finished Goods") -> 0 | C7: =SUMIFS('Sales Transactions Raw Data'!V:V,'Sales Transactions Raw Data'!G:G,"Ola-Mate-R-16oz-12pk",'Sales Transactions Raw Data'!S:S,"amazon-us",'Sales Transactions Raw Data'!J:J,"Finished Goods") -> 0 | D7: =SUMIFS('Sales Transactions Raw Data'!V:V,'Sales Transactions Raw Data'!G:G,"Ola-Mate-R-16oz-12pk",'Sales Transactions Raw Data'!S:S,"Shopify web",'Sales Transactions Raw Data'!J:J,"Finished Goods") -> 0 | E7: =SUMIFS('Sales Transactions Raw Data'!V:V,'Sales Transactions Raw Data'!G:G,"Ola-Mate-R-16oz-12pk",'Sales Transactions Raw Data'!S:S,"Shopify POS",'Sales Transactions Raw Data'!J:J,"Finished Goods") -> 0 | F7: =SUMIFS('Sales Transactions Raw Data'!V:V,'Sales Transactions Raw Data'!G:G,"Ola-Mate-R-16oz-12pk",'Sales Transactions Raw Data'!S:S,"Shopify admin",'Sales Transactions Raw Data'!J:J,"Finished Goods") -> 0 | G7: =SUMIFS('Sales Transactions Raw Data'!V:V,'Sales Transactions Raw Data'!G:G,"Ola-Mate-R-16oz-12pk",'Sales Transactions Raw Data'!S:S,"subscription_contract",'Sales Transactions Raw Data'!J:J,"Finished Goods") -> 0 | H7: =SUMIFS('Sales Transactions Raw Data'!V:V,'Sales Transactions Raw Data'!G:G,"Ola-Mate-R-16oz-12pk",'Sales Transactions Raw Data'!S:S,"subscription_contract_checkout_one",'Sales Transactions Raw Data'!J:J,"Finished Goods") -> 0 | I7: =SUMIFS('Sales Transactions Raw Data'!V:V,'Sales Transactions Raw Data'!G:G,"Ola-Mate-R-16oz-12pk",'Sales Transactions Raw Data'!S:S,"296827748353",'Sales Transactions Raw Data'!J:J,"Finished Goods") -> 0 | J7: =SUMIFS('Sales Transactions Raw Data'!V:V,'Sales Transactions Raw Data'!G:G,"Ola-Mate-R-16oz-12pk",'Sales Transactions Raw Data'!S:S,"faire",'Sales Transactions Raw Data'!J:J,"Finished Goods") -> 0 | K7: =SUMIFS('Sales Transactions Raw Data'!V:V,'Sales Transactions Raw Data'!G:G,"Ola-Mate-R-16oz-12pk",'Sales Transactions Raw Data'!S:S,"tiktok",'Sales Transactions Raw Data'!J:J,"Finished Goods") -> 0 | L7: =SUMIFS('Sales Transactions Raw Data'!V:V,'Sales Transactions Raw Data'!G:G,"Ola-Mate-R-16oz-12pk",'Sales Transactions Raw Data'!S:S,"4901177",'Sales Transactions Raw Data'!J:J,"Finished Goods") -> 0 | M7: =SUMIFS('Sales Transactions Raw Data'!V:V,'Sales Transactions Raw Data'!G:G,"Ola-Mate-R-16oz-12pk",'Sales Transactions Raw Data'!S:S,"3890849",'Sales Transactions Raw Data'!J:J,"Finished Goods") -> 0 | N7: =SUM(B7:M7) -> 0
