Workbook

Sheet 📋 Cover & Index
A2: {{COMPANY_NAME}}
A3: Monthly Controller Reporting Model
A4: Powered by Cin7 Core | Multi-Channel Ecommerce & Wholesale
A5: Data Period: {{DATA_PERIOD}} | Generated: {{GENERATED_DATE}}
A8: PERFORMANCE SNAPSHOT
A9: Total Revenue | C9: Gross Profit | E9: Gross Margin % | G9: Net Contribution
A10: ='KPI Dashboard'!B5 -> 0 | C10: ='KPI Dashboard'!D6 -> 0 | E10: ='KPI Dashboard'!B7 -> - | G10: ='KPI Dashboard'!D7 -> 0
A11: INVENTORY ALERTS → 🔴 Critical: 0 | 🟡 Low Stock: 1 | 🟢 Healthy: 3 | 🔵 Overstock: 4
A13: WORKBOOK INDEX
A14: # | B14: Sheet Name | C14: Type | D14: Purpose | E14: Updated By | F14: Frequency | G14: Data Source | H14: Status
A15: 1 | B15: Cost Inputs | C15: 📝 Input | D15: Manual entry of Ad Spend (by channel) and Warehouse/Fulfillment costs by month | E15: Controller | F15: Monthly | G15: Accounting Invoices | H15: ✅ Active
A16: 2 | B16: Sales Trend Analysis | C16: 📊 Analysis | D16: Revenue, COGS, Gross Profit & MoM Growth % across 6 channels × 6 months | E16: Auto | F16: Monthly | G16: Cin7 Core Export | H16: ✅ Active
A17: 3 | B17: Product Margin Analysis | C17: 📊 Analysis | D17: Revenue, COGS, GM%, Avg Sell Price & Avg COGS per unit by SKU and Category | E17: Auto | F17: Monthly | G17: Cin7 Core Export | H17: ✅ Active
A18: 4 | B18: COGS & Profitability by Channel | C18: 📊 Analysis | D18: Product × Channel revenue & COGS matrix with GM% per channel | E18: Auto | F18: Monthly | G18: Cin7 Core Export | H18: ✅ Active
A19: 5 | B19: Inventory & MOS Analysis | C19: 📦 Inventory | D19: Current stock by location, 3-month avg velocity, MOS calculation & 🔴🟡🟢🔵 alerts | E19: Auto | F19: Weekly | G19: Cin7 Core Export | H19: ✅ Active
A20: 6 | B20: Inventory Movements | C20: 📦 Inventory | D20: Units Sold, Units Purchased & Net Movement per SKU across all months | E20: Auto | F20: Monthly | G20: Cin7 Core + Purchase Data | H20: ✅ Active
A21: 7 | B21: Sales Dashboard | C21: 📈 Dashboard | D21: 3 visual charts: Revenue by Channel (bar), Monthly Trend (line), Product Mix (pie) | E21: Auto | F21: Monthly | G21: Calculated Sheets | H21: ✅ Active
A22: 8 | B22: Profitability Dashboard | C22: 📈 Dashboard | D22: Full P&L waterfall: Revenue → COGS → Gross Profit → Ad Spend → Fulfillment → Net Contribution | E22: Auto | F22: Monthly | G22: Calculated + Cost Inputs | H22: ✅ Active
A23: 9 | B23: KPI Dashboard | C23: 🎯 Executive | D23: One-page scorecard: Revenue, Margins, Channel Mix, Top Products, Inventory Alerts | E23: Auto | F23: Monthly | G23: All Sheets | H23: ✅ Active
A24: 10 | B24: Weekly Order Tracker | C24: ⚠️ Risk | D24: Invoice & shipment status breakdown, revenue at risk (Draft/Unshipped), monthly activity summary | E24: Auto | F24: Weekly | G24: Cin7 Core Export | H24: ✅ Active
A25: — | B25: Sales Transactions Raw Data | C25: 🗄️ Raw Data | D25: Source: Cin7 Core sales export — DO NOT EDIT. Paste new data here monthly | E25: Controller | F25: Monthly | G25: Cin7 Core | H25: 📥 Paste Here
A26: — | B26: Inventory On Hand Raw Data | C26: 🗄️ Raw Data | D26: Source: Cin7 Core inventory snapshot — DO NOT EDIT. Paste new data here | E26: Controller | F26: Weekly | G26: Cin7 Core | H26: 📥 Paste Here
A27: — | B27: Purchase Transactions Raw data | C27: 🗄️ Raw Data | D27: Source: Cin7 Core purchase export — DO NOT EDIT. Paste new data here monthly | E27: Controller | F27: Monthly | G27: Cin7 Core | H27: 📥 Paste Here
A30: CONTROLLER RECOMMENDATIONS & INSIGHTS
A31: # | B31: Category | C31: Finding | D31: Recommendation | E31: Priority | F31: Owner | G31: Action By | H31: Status
A32: 1 | B32: Example | C32: EXAMPLE — TEMPLATE INSTRUCTION | D32: Example recommendation | E32: Medium | F32: Unassigned | G32: Pending | H32: Not Started
A45: HOW TO REFRESH THIS MODEL (Monthly Process)
A46: Step | B46: Action | C46: Detail
A47: Step 1 | B47: Export from Cin7 Core | C47: Run: Sales by Product Details report → export to CSV. Paste into 'Sales Transactions Raw Data' tab (replace all rows, keep headers).
A48: Step 2 | B48: Refresh Inventory Snapshot | C48: Export Cin7 Core → Inventory On Hand report → paste into 'Inventory On Hand Raw Data' tab.
A49: Step 3 | B49: Refresh Purchase Transactions | C49: Export Cin7 Core → Purchase Orders report → paste into 'Purchase Transactions Raw data' tab.
A50: Step 4 | B50: Update Cost Inputs | C50: Open 'Cost Inputs' tab. Enter Ad Spend invoices (Amazon Ads, Shopify/Google, TikTok, Other) and 3PL/Warehouse/FBA fees for the new month column.
A51: Step 5 | B51: Update MOS Month Window | C51: In 'Inventory & MOS Analysis' tab, update the 3 most recent months in the avg sales formulas (columns I5:I12) to reflect the latest 3 months.
A52: Step 6 | B52: Review KPI Dashboard | C52: Go to 'KPI Dashboard' — all metrics auto-refresh. Update the Inventory Alert counts from 'Inventory & MOS Analysis'.
A53: Step 7 | B53: Review Recommendations | C53: Return to this Cover sheet. Mark completed items ✅ in column H. Add new findings as needed.

Sheet KPI Dashboard
A1: {{COMPANY_NAME}} — Controller KPI Dashboard
A2: All-period summary | Finished Goods only | Update month references in Sales Trend Analysis as new data flows in
A4: REVENUE & PROFITABILITY
A5: Total Revenue (All Channels) | B5: =SUMIFS('Sales Transactions Raw Data'!V:V,'Sales Transactions Raw Data'!J:J,"Finished Goods") -> 0 | C5: Total Units Sold | D5: =SUMIFS('Sales Transactions Raw Data'!T:T,'Sales Transactions Raw Data'!J:J,"Finished Goods") -> 0
A6: Total COGS | B6: =SUMIFS('Sales Transactions Raw Data'!W:W,'Sales Transactions Raw Data'!J:J,"Finished Goods") -> 0 | C6: Gross Profit | D6: =B5-B6 -> 0
A7: Gross Margin % | B7: =IF(B5=0,"-",D6/B5) -> - | C7: Net Contribution (after Ad+Fulfillment) | D7: ='Profitability Dashboard'!L12 -> 0
A8: Net Margin % | B8: =IF(B5=0,"-",'Profitability Dashboard'!L13) -> - | C8: Avg Sell Price / Unit | D8: =IF(D5=0,"-",B5/D5) -> -
A10: CHANNEL PERFORMANCE
A11: Channel | B11: Revenue | C11: GM% | D11: Revenue Mix
A12: Amazon | B12: =SUMIFS('Sales Transactions Raw Data'!V:V,'Sales Transactions Raw Data'!S:S,"amazon",'Sales Transactions Raw Data'!J:J,"Finished Goods") -> 0 | C12: ='COGS & Profitability by Channel'!B22 -> - | D12: =IF($B$5=0,"-",B12/$B$5) -> -
A13: Amazon Retail (amazon-us) | B13: =SUMIFS('Sales Transactions Raw Data'!V:V,'Sales Transactions Raw Data'!S:S,"amazon-us",'Sales Transactions Raw Data'!J:J,"Finished Goods") -> 0 | C13: ='COGS & Profitability by Channel'!C22 -> - | D13: =IF($B$5=0,"-",B13/$B$5) -> -
A14: Shopify Web | B14: =SUMIFS('Sales Transactions Raw Data'!V:V,'Sales Transactions Raw Data'!S:S,"Shopify web",'Sales Transactions Raw Data'!J:J,"Finished Goods") -> 0 | C14: ='COGS & Profitability by Channel'!D22 -> - | D14: =IF($B$5=0,"-",B14/$B$5) -> -
A15: Shopify POS | B15: =SUMIFS('Sales Transactions Raw Data'!V:V,'Sales Transactions Raw Data'!S:S,"Shopify POS",'Sales Transactions Raw Data'!J:J,"Finished Goods") -> 0 | C15: ='COGS & Profitability by Channel'!E22 -> - | D15: =IF($B$5=0,"-",B15/$B$5) -> -
A16: Shopify Admin | B16: =SUMIFS('Sales Transactions Raw Data'!V:V,'Sales Transactions Raw Data'!S:S,"Shopify admin",'Sales Transactions Raw Data'!J:J,"Finished Goods") -> 0 | C16: ='COGS & Profitability by Channel'!F22 -> - | D16: =IF($B$5=0,"-",B16/$B$5) -> -
A17: Subscriptions (contract) | B17: =SUMIFS('Sales Transactions Raw Data'!V:V,'Sales Transactions Raw Data'!S:S,"subscription_contract",'Sales Transactions Raw Data'!J:J,"Finished Goods") -> 0 | C17: ='COGS & Profitability by Channel'!G22 -> - | D17: =IF($B$5=0,"-",B17/$B$5) -> -
A18: Subscriptions (checkout) | B18: =SUMIFS('Sales Transactions Raw Data'!V:V,'Sales Transactions Raw Data'!S:S,"subscription_contract_checkout_one",'Sales Transactions Raw Data'!J:J,"Finished Goods") -> 0 | C18: ='COGS & Profitability by Channel'!H22 -> - | D18: =IF($B$5=0,"-",B18/$B$5) -> -
A19: Wholesale (296827748353) | B19: =SUMIFS('Sales Transactions Raw Data'!V:V,'Sales Transactions Raw Data'!S:S,"296827748353",'Sales Transactions Raw Data'!J:J,"Finished Goods") -> 0 | C19: ='COGS & Profitability by Channel'!I22 -> - | D19: =IF($B$5=0,"-",B19/$B$5) -> -
A20: Faire (Wholesale Mkt) | B20: =SUMIFS('Sales Transactions Raw Data'!V:V,'Sales Transactions Raw Data'!S:S,"faire",'Sales Transactions Raw Data'!J:J,"Finished Goods") -> 0 | C20: ='COGS & Profitability by Channel'!J22 -> - | D20: =IF($B$5=0,"-",B20/$B$5) -> -
A21: TikTok Shop | B21: =SUMIFS('Sales Transactions Raw Data'!V:V,'Sales Transactions Raw Data'!S:S,"tiktok",'Sales Transactions Raw Data'!J:J,"Finished Goods") -> 0 | C21: ='COGS & Profitability by Channel'!K22 -> - | D21: =IF($B$5=0,"-",B21/$B$5) -> -
A22: 16oz Variety 12pk | B22: ='Product Margin Analysis'!C5 -> 0 | C22: ='Product Margin Analysis'!F5 -> - | D22: ='Product Margin Analysis'!B5 -> 0
A23: 16oz Berry Coconut 12pk | B23: ='Product Margin Analysis'!C6 -> 0 | C23: ='Product Margin Analysis'!F6 -> - | D23: ='Product Margin Analysis'!B6 -> 0
A24: 16oz Raspberry 12pk | B24: ='Product Margin Analysis'!C7 -> 0 | C24: ='Product Margin Analysis'!F7 -> - | D24: ='Product Margin Analysis'!B7 -> 0
A25: 16oz Grapefruit Ginger 12pk | B25: ='Product Margin Analysis'!C8 -> 0 | C25: ='Product Margin Analysis'!F8 -> - | D25: ='Product Margin Analysis'!B8 -> 0
A26: 16oz Starter 4pk | B26: ='Product Margin Analysis'!C9 -> 0 | C26: ='Product Margin Analysis'!F9 -> - | D26: ='Product Margin Analysis'!B9 -> 0
A27: Loose Cans (all flavours) | B27: ='Product Margin Analysis'!C10 -> 0 | C27: ='Product Margin Analysis'!F10 -> - | D27: ='Product Margin Analysis'!B10 -> 0
A30: INVENTORY STOCK ALERTS (Current Snapshot)
A31: 🔴 CRITICAL (< 1 month) | B31: ='Inventory & MOS Analysis'!B16 -> 0 | C31: SKUs
A32: 🟡 LOW (1–2 months) | B32: ='Inventory & MOS Analysis'!B17 -> 0 | C32: SKUs
A33: 🟢 HEALTHY (2–6 months) | B33: ='Inventory & MOS Analysis'!B18 -> 0 | C33: SKUs
A34: 🔵 OVERSTOCK (> 6 months) | B34: ='Inventory & MOS Analysis'!B19 -> 0 | C34: SKUs

Sheet Weekly Order Tracker
A1: Weekly Order Tracker — Open Items & Risk Flags
A2: Tracks open/pending orders by invoice & shipment status | Update 'As Of Date' in B3 each week
A3: As Of Date (Today): | B3: =TODAY() -> 46258
A5: ORDER STATUS SUMMARY
A6: Status | B6: # Orders | C6: Revenue Value | D6: % of Total | E6: COGS | F6: Gross Profit
A7: Invoiced | B7: =COUNTIFS('Sales Transactions Raw Data'!N:N,"Invoiced") -> 0 | C7: =SUMIFS('Sales Transactions Raw Data'!V:V,'Sales Transactions Raw Data'!N:N,"Invoiced") -> 0 | D7: =IF(C9=0,"-",C7/C9) -> - | E7: =SUMIFS('Sales Transactions Raw Data'!W:W,'Sales Transactions Raw Data'!N:N,"Invoiced") -> 0 | F7: =C7-E7 -> 0
A8: Invoiced / credited | B8: =COUNTIFS('Sales Transactions Raw Data'!N:N,"Invoiced / credited") -> 0 | C8: =SUMIFS('Sales Transactions Raw Data'!V:V,'Sales Transactions Raw Data'!N:N,"Invoiced / credited") -> 0 | D8: =IF(C9=0,"-",C8/C9) -> - | E8: =SUMIFS('Sales Transactions Raw Data'!W:W,'Sales Transactions Raw Data'!N:N,"Invoiced / credited") -> 0 | F8: =C8-E8 -> 0
A9: TOTAL | B9: =SUM(B7:B8) -> 0 | C9: =SUM(C7:C8) -> 0 | D9: 1 | E9: =SUM(E7:E8) -> 0 | F9: =SUM(F7:F8) -> 0
A11: SHIPMENT STATUS SUMMARY
A12: Shipment Status | B12: # Lines | C12: Revenue Value | D12: % of Total | E12: COGS | F12: Gross Profit
A13: Shipped | B13: =COUNTIFS('Sales Transactions Raw Data'!P:P,"Shipped") -> 0 | C13: =SUMIFS('Sales Transactions Raw Data'!V:V,'Sales Transactions Raw Data'!P:P,"Shipped") -> 0 | D13: =IF(C16=0,"-",C13/C16) -> - | E13: =SUMIFS('Sales Transactions Raw Data'!W:W,'Sales Transactions Raw Data'!P:P,"Shipped") -> 0 | F13: =C13-E13 -> 0
A14: Unshipped / Pending | B14: =COUNTIFS('Sales Transactions Raw Data'!P:P,"<>Shipped",'Sales Transactions Raw Data'!P:P,"<>") -> 1 | C14: =SUMIFS('Sales Transactions Raw Data'!V:V,'Sales Transactions Raw Data'!P:P,"<>Shipped",'Sales Transactions Raw Data'!P:P,"<>") -> 0 | D14: =IF(C16=0,"-",C14/C16) -> - | E14: =SUMIFS('Sales Transactions Raw Data'!W:W,'Sales Transactions Raw Data'!P:P,"<>Shipped",'Sales Transactions Raw Data'!P:P,"<>") -> 0 | F14: =C14-E14 -> 0
A15: Partially Shipped | B15: =0 -> 0 | C15: 0 | D15: =IF(C16=0,"-",C15/C16) -> - | E15: 0 | F15: =C15-E15 -> 0
A16: TOTAL | B16: =SUM(B13:B15) -> 1 | C16: =SUM(C13:C15) -> 0 | D16: 1 | E16: =SUM(E13:E15) -> 0 | F16: =SUM(F13:F15) -> 0
A18: OPEN & PENDING ORDERS — RISK TRACKER
A19: Note: The list below summarises open orders (Invoice Status = Draft or Shipment Status ≠ Shipped). For the full transaction-level view, apply filters on the raw data sheet (columns N & O).
A21: Risk Category | B21: # Orders | C21: Revenue at Risk | D21: Avg Order Value | E21: % of Total Revenue | F21: Months Active | G21: Action
A22: 📋 Invoiced / credited (adjustments) | B22: =COUNTIFS('Sales Transactions Raw Data'!N:N,"Invoiced / credited") -> 0 | C22: =SUMIFS('Sales Transactions Raw Data'!V:V,'Sales Transactions Raw Data'!N:N,"Invoiced / credited") -> 0 | D22: =IFERROR(C22/B22,"-") -> - | E22: =IFERROR(C22/'KPI Dashboard'!B5,"-") -> - | F22: Credits/adjustments | G22: Review credit memos
A23: ⚠️ Unshipped / Pending lines (col P ≠ Shipped) | B23: =COUNTIFS('Sales Transactions Raw Data'!P:P,"<>Shipped",'Sales Transactions Raw Data'!P:P,"<>") -> 1 | C23: =SUMIFS('Sales Transactions Raw Data'!V:V,'Sales Transactions Raw Data'!P:P,"<>Shipped",'Sales Transactions Raw Data'!P:P,"<>") -> 0 | D23: =IFERROR(C23/B23,"-") -> 0 | E23: =IFERROR(C23/'KPI Dashboard'!B5,"-") -> - | F23: Fulfillment risk | G23: Chase fulfillment immediately
A24: 📦 Partially Shipped | B24: =COUNTIFS('Sales Transactions Raw Data'!O:O,"Partially Shipped") -> 0 | C24: =SUMIFS('Sales Transactions Raw Data'!V:V,'Sales Transactions Raw Data'!O:O,"Partially Shipped") -> 0 | D24: =IFERROR(C24/B24,"-") -> - | E24: =IFERROR(C24/'KPI Dashboard'!B5,"-") -> - | F24: "" | G24: Follow up on remainder
A27: MONTHLY ORDER ACTIVITY SUMMARY
A28: Month | B28: Total Orders | C28: Invoiced Orders | D28: Draft Orders | E28: Shipped (col P) | F28: Not Shipped (col P) | G28: Revenue | H28: COGS
A29: 45717 | B29: =COUNTIFS('Sales Transactions Raw Data'!B:B,"March",'Sales Transactions Raw Data'!A:A,2025) -> 0 | C29: =COUNTIFS('Sales Transactions Raw Data'!B:B,"March",'Sales Transactions Raw Data'!A:A,2025,'Sales Transactions Raw Data'!N:N,"Invoiced")+COUNTIFS('Sales Transactions Raw Data'!B:B,"March",'Sales Transactions Raw Data'!A:A,2025,'Sales Transactions Raw Data'!N:N,"Invoiced / credited") -> 0 | D29: =0 -> 0 | E29: =COUNTIFS('Sales Transactions Raw Data'!B:B,"March",'Sales Transactions Raw Data'!A:A,2025,'Sales Transactions Raw Data'!P:P,"Shipped") -> 0 | F29: =COUNTIFS('Sales Transactions Raw Data'!B:B,"March",'Sales Transactions Raw Data'!A:A,2025,'Sales Transactions Raw Data'!P:P,"<>Shipped",'Sales Transactions Raw Data'!P:P,"<>") -> 0 | G29: =SUMIFS('Sales Transactions Raw Data'!V:V,'Sales Transactions Raw Data'!B:B,"March",'Sales Transactions Raw Data'!A:A,2025) -> 0 | H29: =SUMIFS('Sales Transactions Raw Data'!W:W,'Sales Transactions Raw Data'!B:B,"March",'Sales Transactions Raw Data'!A:A,2025) -> 0
A30: 45839 | B30: =COUNTIFS('Sales Transactions Raw Data'!B:B,"July",'Sales Transactions Raw Data'!A:A,2025) -> 0 | C30: =COUNTIFS('Sales Transactions Raw Data'!B:B,"July",'Sales Transactions Raw Data'!A:A,2025,'Sales Transactions Raw Data'!N:N,"Invoiced")+COUNTIFS('Sales Transactions Raw Data'!B:B,"July",'Sales Transactions Raw Data'!A:A,2025,'Sales Transactions Raw Data'!N:N,"Invoiced / credited") -> 0 | D30: =0 -> 0 | E30: =COUNTIFS('Sales Transactions Raw Data'!B:B,"July",'Sales Transactions Raw Data'!A:A,2025,'Sales Transactions Raw Data'!P:P,"Shipped") -> 0 | F30: =COUNTIFS('Sales Transactions Raw Data'!B:B,"July",'Sales Transactions Raw Data'!A:A,2025,'Sales Transactions Raw Data'!P:P,"<>Shipped",'Sales Transactions Raw Data'!P:P,"<>") -> 0 | G30: =SUMIFS('Sales Transactions Raw Data'!V:V,'Sales Transactions Raw Data'!B:B,"July",'Sales Transactions Raw Data'!A:A,2025) -> 0 | H30: =SUMIFS('Sales Transactions Raw Data'!W:W,'Sales Transactions Raw Data'!B:B,"July",'Sales Transactions Raw Data'!A:A,2025) -> 0
A31: 45870 | B31: =COUNTIFS('Sales Transactions Raw Data'!B:B,"August",'Sales Transactions Raw Data'!A:A,2025) -> 0 | C31: =COUNTIFS('Sales Transactions Raw Data'!B:B,"August",'Sales Transactions Raw Data'!A:A,2025,'Sales Transactions Raw Data'!N:N,"Invoiced")+COUNTIFS('Sales Transactions Raw Data'!B:B,"August",'Sales Transactions Raw Data'!A:A,2025,'Sales Transactions Raw Data'!N:N,"Invoiced / credited") -> 0 | D31: =0 -> 0 | E31: =COUNTIFS('Sales Transactions Raw Data'!B:B,"August",'Sales Transactions Raw Data'!A:A,2025,'Sales Transactions Raw Data'!P:P,"Shipped") -> 0 | F31: =COUNTIFS('Sales Transactions Raw Data'!B:B,"August",'Sales Transactions Raw Data'!A:A,2025,'Sales Transactions Raw Data'!P:P,"<>Shipped",'Sales Transactions Raw Data'!P:P,"<>") -> 0 | G31: =SUMIFS('Sales Transactions Raw Data'!V:V,'Sales Transactions Raw Data'!B:B,"August",'Sales Transactions Raw Data'!A:A,2025) -> 0 | H31: =SUMIFS('Sales Transactions Raw Data'!W:W,'Sales Transactions Raw Data'!B:B,"August",'Sales Transactions Raw Data'!A:A,2025) -> 0
A32: 45901 | B32: =COUNTIFS('Sales Transactions Raw Data'!B:B,"September",'Sales Transactions Raw Data'!A:A,2025) -> 0 | C32: =COUNTIFS('Sales Transactions Raw Data'!B:B,"September",'Sales Transactions Raw Data'!A:A,2025,'Sales Transactions Raw Data'!N:N,"Invoiced")+COUNTIFS('Sales Transactions Raw Data'!B:B,"September",'Sales Transactions Raw Data'!A:A,2025,'Sales Transactions Raw Data'!N:N,"Invoiced / credited") -> 0 | D32: =0 -> 0 | E32: =COUNTIFS('Sales Transactions Raw Data'!B:B,"September",'Sales Transactions Raw Data'!A:A,2025,'Sales Transactions Raw Data'!P:P,"Shipped") -> 0 | F32: =COUNTIFS('Sales Transactions Raw Data'!B:B,"September",'Sales Transactions Raw Data'!A:A,2025,'Sales Transactions Raw Data'!P:P,"<>Shipped",'Sales Transactions Raw Data'!P:P,"<>") -> 0 | G32: =SUMIFS('Sales Transactions Raw Data'!V:V,'Sales Transactions Raw Data'!B:B,"September",'Sales Transactions Raw Data'!A:A,2025) -> 0 | H32: =SUMIFS('Sales Transactions Raw Data'!W:W,'Sales Transactions Raw Data'!B:B,"September",'Sales Transactions Raw Data'!A:A,2025) -> 0
A33: 45931 | B33: =COUNTIFS('Sales Transactions Raw Data'!B:B,"October",'Sales Transactions Raw Data'!A:A,2025) -> 0 | C33: =COUNTIFS('Sales Transactions Raw Data'!B:B,"October",'Sales Transactions Raw Data'!A:A,2025,'Sales Transactions Raw Data'!N:N,"Invoiced")+COUNTIFS('Sales Transactions Raw Data'!B:B,"October",'Sales Transactions Raw Data'!A:A,2025,'Sales Transactions Raw Data'!N:N,"Invoiced / credited") -> 0 | D33: =0 -> 0 | E33: =COUNTIFS('Sales Transactions Raw Data'!B:B,"October",'Sales Transactions Raw Data'!A:A,2025,'Sales Transactions Raw Data'!P:P,"Shipped") -> 0 | F33: =COUNTIFS('Sales Transactions Raw Data'!B:B,"October",'Sales Transactions Raw Data'!A:A,2025,'Sales Transactions Raw Data'!P:P,"<>Shipped",'Sales Transactions Raw Data'!P:P,"<>") -> 0 | G33: =SUMIFS('Sales Transactions Raw Data'!V:V,'Sales Transactions Raw Data'!B:B,"October",'Sales Transactions Raw Data'!A:A,2025) -> 0 | H33: =SUMIFS('Sales Transactions Raw Data'!W:W,'Sales Transactions Raw Data'!B:B,"October",'Sales Transactions Raw Data'!A:A,2025) -> 0
A34: 45962 | B34: =COUNTIFS('Sales Transactions Raw Data'!B:B,"November",'Sales Transactions Raw Data'!A:A,2025) -> 0 | C34: =COUNTIFS('Sales Transactions Raw Data'!B:B,"November",'Sales Transactions Raw Data'!A:A,2025,'Sales Transactions Raw Data'!N:N,"Invoiced")+COUNTIFS('Sales Transactions Raw Data'!B:B,"November",'Sales Transactions Raw Data'!A:A,2025,'Sales Transactions Raw Data'!N:N,"Invoiced / credited") -> 0 | D34: =0 -> 0 | E34: =COUNTIFS('Sales Transactions Raw Data'!B:B,"November",'Sales Transactions Raw Data'!A:A,2025,'Sales Transactions Raw Data'!P:P,"Shipped") -> 0 | F34: =COUNTIFS('Sales Transactions Raw Data'!B:B,"November",'Sales Transactions Raw Data'!A:A,2025,'Sales Transactions Raw Data'!P:P,"<>Shipped",'Sales Transactions Raw Data'!P:P,"<>") -> 0 | G34: =SUMIFS('Sales Transactions Raw Data'!V:V,'Sales Transactions Raw Data'!B:B,"November",'Sales Transactions Raw Data'!A:A,2025) -> 0 | H34: =SUMIFS('Sales Transactions Raw Data'!W:W,'Sales Transactions Raw Data'!B:B,"November",'Sales Transactions Raw Data'!A:A,2025) -> 0
A35: TOTAL | B35: =SUM(B29:B34) -> 0 | C35: =SUM(C29:C34) -> 0 | D35: =SUM(D29:D34) -> 0 | E35: =SUM(E29:E34) -> 0 | F35: =SUM(F29:F34) -> 0 | G35: =SUM(G29:G34) -> 0 | H35: =SUM(H29:H34) -> 0

Sheet Sales Trend Analysis
A1: Sales Trend Analysis — Monthly by Channel
A3: REVENUE BY CHANNEL ($) | B3: 46106 | C3: 46228 | D3: 46259 | E3: 46290 | F3: 46320 | G3: 46351 | H3: 46381 | I3: 46048 | J3: 46079 | K3: 46107 | L3: Total
A4: Amazon (Seller Central) | B4: =SUMIFS('Sales Transactions Raw Data'!V:V,'Sales Transactions Raw Data'!S:S,"amazon",'Sales Transactions Raw Data'!B:B,"March",'Sales Transactions Raw Data'!A:A,2025,'Sales Transactions Raw Data'!J:J,"Finished Goods") -> 0 | C4: =SUMIFS('Sales Transactions Raw Data'!V:V,'Sales Transactions Raw Data'!S:S,"amazon",'Sales Transactions Raw Data'!B:B,"March",'Sales Transactions Raw Data'!A:A,2025,'Sales Transactions Raw Data'!J:J,"Finished Goods") -> 0 | D4: =SUMIFS('Sales Transactions Raw Data'!V:V,'Sales Transactions Raw Data'!S:S,"amazon",'Sales Transactions Raw Data'!B:B,"July",'Sales Transactions Raw Data'!A:A,2025,'Sales Transactions Raw Data'!J:J,"Finished Goods") -> 0 | E4: =SUMIFS('Sales Transactions Raw Data'!V:V,'Sales Transactions Raw Data'!S:S,"amazon",'Sales Transactions Raw Data'!B:B,"August",'Sales Transactions Raw Data'!A:A,2025,'Sales Transactions Raw Data'!J:J,"Finished Goods") -> 0 | F4: =SUMIFS('Sales Transactions Raw Data'!V:V,'Sales Transactions Raw Data'!S:S,"amazon",'Sales Transactions Raw Data'!B:B,"September",'Sales Transactions Raw Data'!A:A,2025,'Sales Transactions Raw Data'!J:J,"Finished Goods") -> 0 | G4: =SUMIFS('Sales Transactions Raw Data'!V:V,'Sales Transactions Raw Data'!S:S,"amazon",'Sales Transactions Raw Data'!B:B,"October",'Sales Transactions Raw Data'!A:A,2025,'Sales Transactions Raw Data'!J:J,"Finished Goods") -> 0 | H4: =SUMIFS('Sales Transactions Raw Data'!V:V,'Sales Transactions Raw Data'!S:S,"amazon",'Sales Transactions Raw Data'!B:B,"November",'Sales Transactions Raw Data'!A:A,2025,'Sales Transactions Raw Data'!J:J,"Finished Goods") -> 0 | I4: =SUMIFS('Sales Transactions Raw Data'!V:V,'Sales Transactions Raw Data'!S:S,"amazon",'Sales Transactions Raw Data'!B:B,"January",'Sales Transactions Raw Data'!A:A,2026,'Sales Transactions Raw Data'!J:J,"Finished Goods") -> 0 | J4: =SUMIFS('Sales Transactions Raw Data'!V:V,'Sales Transactions Raw Data'!S:S,"amazon",'Sales Transactions Raw Data'!B:B,"February",'Sales Transactions Raw Data'!A:A,2026,'Sales Transactions Raw Data'!J:J,"Finished Goods") -> 0 | K4: =SUMIFS('Sales Transactions Raw Data'!V:V,'Sales Transactions Raw Data'!S:S,"amazon",'Sales Transactions Raw Data'!B:B,"March",'Sales Transactions Raw Data'!A:A,2026,'Sales Transactions Raw Data'!J:J,"Finished Goods") -> 0 | L4: =SUM(B4:K4) -> 0
A5: Amazon Retail / Vendor | B5: =SUMIFS('Sales Transactions Raw Data'!V:V,'Sales Transactions Raw Data'!R:R,"Amazon.com",'Sales Transactions Raw Data'!B:B,"March",'Sales Transactions Raw Data'!A:A,2025,'Sales Transactions Raw Data'!J:J,"Finished Goods") -> 0 | C5: =SUMIFS('Sales Transactions Raw Data'!V:V,'Sales Transactions Raw Data'!S:S,"amazon-us",'Sales Transactions Raw Data'!B:B,"March",'Sales Transactions Raw Data'!A:A,2025,'Sales Transactions Raw Data'!J:J,"Finished Goods") -> 0 | D5: =SUMIFS('Sales Transactions Raw Data'!V:V,'Sales Transactions Raw Data'!S:S,"amazon-us",'Sales Transactions Raw Data'!B:B,"July",'Sales Transactions Raw Data'!A:A,2025,'Sales Transactions Raw Data'!J:J,"Finished Goods") -> 0 | E5: =SUMIFS('Sales Transactions Raw Data'!V:V,'Sales Transactions Raw Data'!S:S,"amazon-us",'Sales Transactions Raw Data'!B:B,"August",'Sales Transactions Raw Data'!A:A,2025,'Sales Transactions Raw Data'!J:J,"Finished Goods") -> 0 | F5: =SUMIFS('Sales Transactions Raw Data'!V:V,'Sales Transactions Raw Data'!S:S,"amazon-us",'Sales Transactions Raw Data'!B:B,"September",'Sales Transactions Raw Data'!A:A,2025,'Sales Transactions Raw Data'!J:J,"Finished Goods") -> 0 | G5: =SUMIFS('Sales Transactions Raw Data'!V:V,'Sales Transactions Raw Data'!S:S,"amazon-us",'Sales Transactions Raw Data'!B:B,"October",'Sales Transactions Raw Data'!A:A,2025,'Sales Transactions Raw Data'!J:J,"Finished Goods") -> 0 | H5: =SUMIFS('Sales Transactions Raw Data'!V:V,'Sales Transactions Raw Data'!S:S,"amazon-us",'Sales Transactions Raw Data'!B:B,"November",'Sales Transactions Raw Data'!A:A,2025,'Sales Transactions Raw Data'!J:J,"Finished Goods") -> 0 | I5: =SUMIFS('Sales Transactions Raw Data'!V:V,'Sales Transactions Raw Data'!R:R,"Amazon.com",'Sales Transactions Raw Data'!B:B,"January",'Sales Transactions Raw Data'!A:A,2026,'Sales Transactions Raw Data'!J:J,"Finished Goods") -> 0 | J5: =SUMIFS('Sales Transactions Raw Data'!V:V,'Sales Transactions Raw Data'!R:R,"Amazon.com",'Sales Transactions Raw Data'!B:B,"February",'Sales Transactions Raw Data'!A:A,2026,'Sales Transactions Raw Data'!J:J,"Finished Goods") -> 0 | K5: =SUMIFS('Sales Transactions Raw Data'!V:V,'Sales Transactions Raw Data'!R:R,"Amazon.com",'Sales Transactions Raw Data'!B:B,"March",'Sales Transactions Raw Data'!A:A,2026,'Sales Transactions Raw Data'!J:J,"Finished Goods") -> 0 | L5: =SUM(B5:K5) -> 0
A6: Shopify Web (D2C) | B6: =SUMIFS('Sales Transactions Raw Data'!V:V,'Sales Transactions Raw Data'!S:S,"Shopify web",'Sales Transactions Raw Data'!B:B,"March",'Sales Transactions Raw Data'!A:A,2025,'Sales Transactions Raw Data'!J:J,"Finished Goods") -> 0 | C6: =SUMIFS('Sales Transactions Raw Data'!V:V,'Sales Transactions Raw Data'!S:S,"Shopify web",'Sales Transactions Raw Data'!B:B,"March",'Sales Transactions Raw Data'!A:A,2025,'Sales Transactions Raw Data'!J:J,"Finished Goods") -> 0 | D6: =SUMIFS('Sales Transactions Raw Data'!V:V,'Sales Transactions Raw Data'!S:S,"Shopify web",'Sales Transactions Raw Data'!B:B,"July",'Sales Transactions Raw Data'!A:A,2025,'Sales Transactions Raw Data'!J:J,"Finished Goods") -> 0 | E6: =SUMIFS('Sales Transactions Raw Data'!V:V,'Sales Transactions Raw Data'!S:S,"Shopify web",'Sales Transactions Raw Data'!B:B,"August",'Sales Transactions Raw Data'!A:A,2025,'Sales Transactions Raw Data'!J:J,"Finished Goods") -> 0 | F6: =SUMIFS('Sales Transactions Raw Data'!V:V,'Sales Transactions Raw Data'!S:S,"Shopify web",'Sales Transactions Raw Data'!B:B,"September",'Sales Transactions Raw Data'!A:A,2025,'Sales Transactions Raw Data'!J:J,"Finished Goods") -> 0 | G6: =SUMIFS('Sales Transactions Raw Data'!V:V,'Sales Transactions Raw Data'!S:S,"Shopify web",'Sales Transactions Raw Data'!B:B,"October",'Sales Transactions Raw Data'!A:A,2025,'Sales Transactions Raw Data'!J:J,"Finished Goods") -> 0 | H6: =SUMIFS('Sales Transactions Raw Data'!V:V,'Sales Transactions Raw Data'!S:S,"Shopify web",'Sales Transactions Raw Data'!B:B,"November",'Sales Transactions Raw Data'!A:A,2025,'Sales Transactions Raw Data'!J:J,"Finished Goods") -> 0 | I6: =SUMIFS('Sales Transactions Raw Data'!V:V,'Sales Transactions Raw Data'!S:S,"Shopify web",'Sales Transactions Raw Data'!B:B,"January",'Sales Transactions Raw Data'!A:A,2026,'Sales Transactions Raw Data'!J:J,"Finished Goods") -> 0 | J6: =SUMIFS('Sales Transactions Raw Data'!V:V,'Sales Transactions Raw Data'!S:S,"Shopify web",'Sales Transactions Raw Data'!B:B,"February",'Sales Transactions Raw Data'!A:A,2026,'Sales Transactions Raw Data'!J:J,"Finished Goods") -> 0 | K6: =SUMIFS('Sales Transactions Raw Data'!V:V,'Sales Transactions Raw Data'!S:S,"Shopify web",'Sales Transactions Raw Data'!B:B,"March",'Sales Transactions Raw Data'!A:A,2026,'Sales Transactions Raw Data'!J:J,"Finished Goods") -> 0 | L6: =SUM(B6:K6) -> 0
A7: Shopify POS (In-store) | B7: =SUMIFS('Sales Transactions Raw Data'!V:V,'Sales Transactions Raw Data'!S:S,"tiktok",'Sales Transactions Raw Data'!B:B,"March",'Sales Transactions Raw Data'!A:A,2025,'Sales Transactions Raw Data'!J:J,"Finished Goods") -> 0 | C7: =SUMIFS('Sales Transactions Raw Data'!V:V,'Sales Transactions Raw Data'!S:S,"Shopify POS",'Sales Transactions Raw Data'!B:B,"March",'Sales Transactions Raw Data'!A:A,2025,'Sales Transactions Raw Data'!J:J,"Finished Goods") -> 0 | D7: =SUMIFS('Sales Transactions Raw Data'!V:V,'Sales Transactions Raw Data'!S:S,"Shopify POS",'Sales Transactions Raw Data'!B:B,"July",'Sales Transactions Raw Data'!A:A,2025,'Sales Transactions Raw Data'!J:J,"Finished Goods") -> 0 | E7: =SUMIFS('Sales Transactions Raw Data'!V:V,'Sales Transactions Raw Data'!S:S,"Shopify POS",'Sales Transactions Raw Data'!B:B,"August",'Sales Transactions Raw Data'!A:A,2025,'Sales Transactions Raw Data'!J:J,"Finished Goods") -> 0 | F7: =SUMIFS('Sales Transactions Raw Data'!V:V,'Sales Transactions Raw Data'!S:S,"Shopify POS",'Sales Transactions Raw Data'!B:B,"September",'Sales Transactions Raw Data'!A:A,2025,'Sales Transactions Raw Data'!J:J,"Finished Goods") -> 0 | G7: =SUMIFS('Sales Transactions Raw Data'!V:V,'Sales Transactions Raw Data'!S:S,"Shopify POS",'Sales Transactions Raw Data'!B:B,"October",'Sales Transactions Raw Data'!A:A,2025,'Sales Transactions Raw Data'!J:J,"Finished Goods") -> 0 | H7: =SUMIFS('Sales Transactions Raw Data'!V:V,'Sales Transactions Raw Data'!S:S,"Shopify POS",'Sales Transactions Raw Data'!B:B,"November",'Sales Transactions Raw Data'!A:A,2025,'Sales Transactions Raw Data'!J:J,"Finished Goods") -> 0 | I7: =SUMIFS('Sales Transactions Raw Data'!V:V,'Sales Transactions Raw Data'!S:S,"tiktok",'Sales Transactions Raw Data'!B:B,"January",'Sales Transactions Raw Data'!A:A,2026,'Sales Transactions Raw Data'!J:J,"Finished Goods") -> 0 | J7: =SUMIFS('Sales Transactions Raw Data'!V:V,'Sales Transactions Raw Data'!S:S,"tiktok",'Sales Transactions Raw Data'!B:B,"February",'Sales Transactions Raw Data'!A:A,2026,'Sales Transactions Raw Data'!J:J,"Finished Goods") -> 0 | K7: =SUMIFS('Sales Transactions Raw Data'!V:V,'Sales Transactions Raw Data'!S:S,"tiktok",'Sales Transactions Raw Data'!B:B,"March",'Sales Transactions Raw Data'!A:A,2026,'Sales Transactions Raw Data'!J:J,"Finished Goods") -> 0 | L7: =SUM(B7:K7) -> 0
A8: Shopify Admin (Samples/Manual) | B8: =SUMIFS('Sales Transactions Raw Data'!V:V,'Sales Transactions Raw Data'!S:S,"296827748353",'Sales Transactions Raw Data'!B:B,"March",'Sales Transactions Raw Data'!A:A,2025,'Sales Transactions Raw Data'!J:J,"Finished Goods") -> 0 | C8: =SUMIFS('Sales Transactions Raw Data'!V:V,'Sales Transactions Raw Data'!S:S,"Shopify admin",'Sales Transactions Raw Data'!B:B,"March",'Sales Transactions Raw Data'!A:A,2025,'Sales Transactions Raw Data'!J:J,"Finished Goods") -> 0 | D8: =SUMIFS('Sales Transactions Raw Data'!V:V,'Sales Transactions Raw Data'!S:S,"Shopify admin",'Sales Transactions Raw Data'!B:B,"July",'Sales Transactions Raw Data'!A:A,2025,'Sales Transactions Raw Data'!J:J,"Finished Goods") -> 0 | E8: =SUMIFS('Sales Transactions Raw Data'!V:V,'Sales Transactions Raw Data'!S:S,"Shopify admin",'Sales Transactions Raw Data'!B:B,"August",'Sales Transactions Raw Data'!A:A,2025,'Sales Transactions Raw Data'!J:J,"Finished Goods") -> 0 | F8: =SUMIFS('Sales Transactions Raw Data'!V:V,'Sales Transactions Raw Data'!S:S,"Shopify admin",'Sales Transactions Raw Data'!B:B,"September",'Sales Transactions Raw Data'!A:A,2025,'Sales Transactions Raw Data'!J:J,"Finished Goods") -> 0 | G8: =SUMIFS('Sales Transactions Raw Data'!V:V,'Sales Transactions Raw Data'!S:S,"Shopify admin",'Sales Transactions Raw Data'!B:B,"October",'Sales Transactions Raw Data'!A:A,2025,'Sales Transactions Raw Data'!J:J,"Finished Goods") -> 0 | H8: =SUMIFS('Sales Transactions Raw Data'!V:V,'Sales Transactions Raw Data'!S:S,"Shopify admin",'Sales Transactions Raw Data'!B:B,"November",'Sales Transactions Raw Data'!A:A,2025,'Sales Transactions Raw Data'!J:J,"Finished Goods") -> 0 | I8: =SUMIFS('Sales Transactions Raw Data'!V:V,'Sales Transactions Raw Data'!S:S,"296827748353",'Sales Transactions Raw Data'!B:B,"January",'Sales Transactions Raw Data'!A:A,2026,'Sales Transactions Raw Data'!J:J,"Finished Goods") -> 0 | J8: =SUMIFS('Sales Transactions Raw Data'!V:V,'Sales Transactions Raw Data'!S:S,"296827748353",'Sales Transactions Raw Data'!B:B,"February",'Sales Transactions Raw Data'!A:A,2026,'Sales Transactions Raw Data'!J:J,"Finished Goods") -> 0 | K8: =SUMIFS('Sales Transactions Raw Data'!V:V,'Sales Transactions Raw Data'!S:S,"296827748353",'Sales Transactions Raw Data'!B:B,"March",'Sales Transactions Raw Data'!A:A,2026,'Sales Transactions Raw Data'!J:J,"Finished Goods") -> 0 | L8: =SUM(B8:K8) -> 0
A9: Subscriptions (contract) | B9: =SUMIFS('Sales Transactions Raw Data'!V:V,'Sales Transactions Raw Data'!S:S,"Shopify POS",'Sales Transactions Raw Data'!B:B,"March",'Sales Transactions Raw Data'!A:A,2025) -> 0 | C9: =SUMIFS('Sales Transactions Raw Data'!V:V,'Sales Transactions Raw Data'!S:S,"subscription_contract",'Sales Transactions Raw Data'!B:B,"March",'Sales Transactions Raw Data'!A:A,2025,'Sales Transactions Raw Data'!J:J,"Finished Goods") -> 0 | D9: =SUMIFS('Sales Transactions Raw Data'!V:V,'Sales Transactions Raw Data'!S:S,"subscription_contract",'Sales Transactions Raw Data'!B:B,"July",'Sales Transactions Raw Data'!A:A,2025,'Sales Transactions Raw Data'!J:J,"Finished Goods") -> 0 | E9: =SUMIFS('Sales Transactions Raw Data'!V:V,'Sales Transactions Raw Data'!S:S,"subscription_contract",'Sales Transactions Raw Data'!B:B,"August",'Sales Transactions Raw Data'!A:A,2025,'Sales Transactions Raw Data'!J:J,"Finished Goods") -> 0 | F9: =SUMIFS('Sales Transactions Raw Data'!V:V,'Sales Transactions Raw Data'!S:S,"subscription_contract",'Sales Transactions Raw Data'!B:B,"September",'Sales Transactions Raw Data'!A:A,2025,'Sales Transactions Raw Data'!J:J,"Finished Goods") -> 0 | G9: =SUMIFS('Sales Transactions Raw Data'!V:V,'Sales Transactions Raw Data'!S:S,"subscription_contract",'Sales Transactions Raw Data'!B:B,"October",'Sales Transactions Raw Data'!A:A,2025,'Sales Transactions Raw Data'!J:J,"Finished Goods") -> 0 | H9: =SUMIFS('Sales Transactions Raw Data'!V:V,'Sales Transactions Raw Data'!S:S,"subscription_contract",'Sales Transactions Raw Data'!B:B,"November",'Sales Transactions Raw Data'!A:A,2025,'Sales Transactions Raw Data'!J:J,"Finished Goods") -> 0 | I9: =SUMIFS('Sales Transactions Raw Data'!V:V,'Sales Transactions Raw Data'!S:S,"Shopify POS",'Sales Transactions Raw Data'!B:B,"January",'Sales Transactions Raw Data'!A:A,2026) -> 0 | J9: =SUMIFS('Sales Transactions Raw Data'!V:V,'Sales Transactions Raw Data'!S:S,"Shopify POS",'Sales Transactions Raw Data'!B:B,"February",'Sales Transactions Raw Data'!A:A,2026) -> 0 | K9: =SUMIFS('Sales Transactions Raw Data'!V:V,'Sales Transactions Raw Data'!S:S,"Shopify POS",'Sales Transactions Raw Data'!B:B,"March",'Sales Transactions Raw Data'!A:A,2026) -> 0 | L9: =SUM(B9:K9) -> 0
A10: Subscriptions (checkout) | B10: =SUMIFS('Sales Transactions Raw Data'!V:V,'Sales Transactions Raw Data'!S:S,"subscription_contract",'Sales Transactions Raw Data'!B:B,"March",'Sales Transactions Raw Data'!A:A,2025,'Sales Transactions Raw Data'!J:J,"Finished Goods")+SUMIFS('Sales Transactions Raw Data'!V:V,'Sales Transactions Raw Data'!S:S,"subscription_contract_checkout_one",'Sales Transactions Raw Data'!B:B,"March",'Sales Transactions Raw Data'!A:A,2025,'Sales Transactions Raw Data'!J:J,"Finished Goods") -> 0 | C10: =SUMIFS('Sales Transactions Raw Data'!V:V,'Sales Transactions Raw Data'!S:S,"subscription_contract_checkout_one",'Sales Transactions Raw Data'!B:B,"March",'Sales Transactions Raw Data'!A:A,2025,'Sales Transactions Raw Data'!J:J,"Finished Goods") -> 0 | D10: =SUMIFS('Sales Transactions Raw Data'!V:V,'Sales Transactions Raw Data'!S:S,"subscription_contract_checkout_one",'Sales Transactions Raw Data'!B:B,"July",'Sales Transactions Raw Data'!A:A,2025,'Sales Transactions Raw Data'!J:J,"Finished Goods") -> 0 | E10: =SUMIFS('Sales Transactions Raw Data'!V:V,'Sales Transactions Raw Data'!S:S,"subscription_contract_checkout_one",'Sales Transactions Raw Data'!B:B,"August",'Sales Transactions Raw Data'!A:A,2025,'Sales Transactions Raw Data'!J:J,"Finished Goods") -> 0 | F10: =SUMIFS('Sales Transactions Raw Data'!V:V,'Sales Transactions Raw Data'!S:S,"subscription_contract_checkout_one",'Sales Transactions Raw Data'!B:B,"September",'Sales Transactions Raw Data'!A:A,2025,'Sales Transactions Raw Data'!J:J,"Finished Goods") -> 0 | G10: =SUMIFS('Sales Transactions Raw Data'!V:V,'Sales Transactions Raw Data'!S:S,"subscription_contract_checkout_one",'Sales Transactions Raw Data'!B:B,"October",'Sales Transactions Raw Data'!A:A,2025,'Sales Transactions Raw Data'!J:J,"Finished Goods") -> 0 | H10: =SUMIFS('Sales Transactions Raw Data'!V:V,'Sales Transactions Raw Data'!S:S,"subscription_contract_checkout_one",'Sales Transactions Raw Data'!B:B,"November",'Sales Transactions Raw Data'!A:A,2025,'Sales Transactions Raw Data'!J:J,"Finished Goods") -> 0 | I10: =SUMIFS('Sales Transactions Raw Data'!V:V,'Sales Transactions Raw Data'!S:S,"subscription_contract",'Sales Transactions Raw Data'!B:B,"January",'Sales Transactions Raw Data'!A:A,2026,'Sales Transactions Raw Data'!J:J,"Finished Goods")+SUMIFS('Sales Transactions Raw Data'!V:V,'Sales Transactions Raw Data'!S:S,"subscription_contract_checkout_one",'Sales Transactions Raw Data'!B:B,"January",'Sales Transactions Raw Data'!A:A,2026,'Sales Transactions Raw Data'!J:J,"Finished Goods") -> 0 | J10: =SUMIFS('Sales Transactions Raw Data'!V:V,'Sales Transactions Raw Data'!S:S,"subscription_contract",'Sales Transactions Raw Data'!B:B,"February",'Sales Transactions Raw Data'!A:A,2026,'Sales Transactions Raw Data'!J:J,"Finished Goods")+SUMIFS('Sales Transactions Raw Data'!V:V,'Sales Transactions Raw Data'!S:S,"subscription_contract_checkout_one",'Sales Transactions Raw Data'!B:B,"February",'Sales Transactions Raw Data'!A:A,2026,'Sales Transactions Raw Data'!J:J,"Finished Goods") -> 0 | K10: =SUMIFS('Sales Transactions Raw Data'!V:V,'Sales Transactions Raw Data'!S:S,"subscription_contract",'Sales Transactions Raw Data'!B:B,"March",'Sales Transactions Raw Data'!A:A,2026,'Sales Transactions Raw Data'!J:J,"Finished Goods")+SUMIFS('Sales Transactions Raw Data'!V:V,'Sales Transactions Raw Data'!S:S,"subscription_contract_checkout_one",'Sales Transactions Raw Data'!B:B,"March",'Sales Transactions Raw Data'!A:A,2026,'Sales Transactions Raw Data'!J:J,"Finished Goods") -> 0 | L10: =SUM(B10:K10) -> 0
A11: Wholesale / Distrib (296827748353) | B11: =SUMIFS('Sales Transactions Raw Data'!V:V,'Sales Transactions Raw Data'!S:S,"Shopify admin",'Sales Transactions Raw Data'!B:B,"March",'Sales Transactions Raw Data'!A:A,2025,'Sales Transactions Raw Data'!J:J,"Finished Goods") -> 0 | C11: =SUMIFS('Sales Transactions Raw Data'!V:V,'Sales Transactions Raw Data'!S:S,"296827748353",'Sales Transactions Raw Data'!B:B,"March",'Sales Transactions Raw Data'!A:A,2025,'Sales Transactions Raw Data'!J:J,"Finished Goods") -> 0 | D11: =SUMIFS('Sales Transactions Raw Data'!V:V,'Sales Transactions Raw Data'!S:S,"296827748353",'Sales Transactions Raw Data'!B:B,"July",'Sales Transactions Raw Data'!A:A,2025,'Sales Transactions Raw Data'!J:J,"Finished Goods") -> 0 | E11: =SUMIFS('Sales Transactions Raw Data'!V:V,'Sales Transactions Raw Data'!S:S,"296827748353",'Sales Transactions Raw Data'!B:B,"August",'Sales Transactions Raw Data'!A:A,2025,'Sales Transactions Raw Data'!J:J,"Finished Goods") -> 0 | F11: =SUMIFS('Sales Transactions Raw Data'!V:V,'Sales Transactions Raw Data'!S:S,"296827748353",'Sales Transactions Raw Data'!B:B,"September",'Sales Transactions Raw Data'!A:A,2025,'Sales Transactions Raw Data'!J:J,"Finished Goods") -> 0 | G11: =SUMIFS('Sales Transactions Raw Data'!V:V,'Sales Transactions Raw Data'!S:S,"296827748353",'Sales Transactions Raw Data'!B:B,"October",'Sales Transactions Raw Data'!A:A,2025,'Sales Transactions Raw Data'!J:J,"Finished Goods") -> 0 | H11: =SUMIFS('Sales Transactions Raw Data'!V:V,'Sales Transactions Raw Data'!S:S,"296827748353",'Sales Transactions Raw Data'!B:B,"November",'Sales Transactions Raw Data'!A:A,2025,'Sales Transactions Raw Data'!J:J,"Finished Goods") -> 0 | I11: =SUMIFS('Sales Transactions Raw Data'!V:V,'Sales Transactions Raw Data'!S:S,"Shopify admin",'Sales Transactions Raw Data'!B:B,"January",'Sales Transactions Raw Data'!A:A,2026,'Sales Transactions Raw Data'!J:J,"Finished Goods") -> 0 | J11: =SUMIFS('Sales Transactions Raw Data'!V:V,'Sales Transactions Raw Data'!S:S,"Shopify admin",'Sales Transactions Raw Data'!B:B,"February",'Sales Transactions Raw Data'!A:A,2026,'Sales Transactions Raw Data'!J:J,"Finished Goods") -> 0 | K11: =SUMIFS('Sales Transactions Raw Data'!V:V,'Sales Transactions Raw Data'!S:S,"Shopify admin",'Sales Transactions Raw Data'!B:B,"March",'Sales Transactions Raw Data'!A:A,2026,'Sales Transactions Raw Data'!J:J,"Finished Goods") -> 0 | L11: =SUM(B11:K11) -> 0
A12: Faire (Wholesale Mkt) | C12: =SUMIFS('Sales Transactions Raw Data'!V:V,'Sales Transactions Raw Data'!S:S,"faire",'Sales Transactions Raw Data'!B:B,"March",'Sales Transactions Raw Data'!A:A,2025,'Sales Transactions Raw Data'!J:J,"Finished Goods") -> 0 | D12: =SUMIFS('Sales Transactions Raw Data'!V:V,'Sales Transactions Raw Data'!S:S,"faire",'Sales Transactions Raw Data'!B:B,"July",'Sales Transactions Raw Data'!A:A,2025,'Sales Transactions Raw Data'!J:J,"Finished Goods") -> 0 | E12: =SUMIFS('Sales Transactions Raw Data'!V:V,'Sales Transactions Raw Data'!S:S,"faire",'Sales Transactions Raw Data'!B:B,"August",'Sales Transactions Raw Data'!A:A,2025,'Sales Transactions Raw Data'!J:J,"Finished Goods") -> 0 | F12: =SUMIFS('Sales Transactions Raw Data'!V:V,'Sales Transactions Raw Data'!S:S,"faire",'Sales Transactions Raw Data'!B:B,"September",'Sales Transactions Raw Data'!A:A,2025,'Sales Transactions Raw Data'!J:J,"Finished Goods") -> 0 | G12: =SUMIFS('Sales Transactions Raw Data'!V:V,'Sales Transactions Raw Data'!S:S,"faire",'Sales Transactions Raw Data'!B:B,"October",'Sales Transactions Raw Data'!A:A,2025,'Sales Transactions Raw Data'!J:J,"Finished Goods") -> 0 | H12: =SUMIFS('Sales Transactions Raw Data'!V:V,'Sales Transactions Raw Data'!S:S,"faire",'Sales Transactions Raw Data'!B:B,"November",'Sales Transactions Raw Data'!A:A,2025,'Sales Transactions Raw Data'!J:J,"Finished Goods") -> 0
A13: TikTok Shop | B13: =SUM(B4:B11) -> 0 | C13: =SUMIFS('Sales Transactions Raw Data'!V:V,'Sales Transactions Raw Data'!S:S,"tiktok",'Sales Transactions Raw Data'!B:B,"March",'Sales Transactions Raw Data'!A:A,2025,'Sales Transactions Raw Data'!J:J,"Finished Goods") -> 0 | D13: =SUMIFS('Sales Transactions Raw Data'!V:V,'Sales Transactions Raw Data'!S:S,"tiktok",'Sales Transactions Raw Data'!B:B,"July",'Sales Transactions Raw Data'!A:A,2025,'Sales Transactions Raw Data'!J:J,"Finished Goods") -> 0 | E13: =SUMIFS('Sales Transactions Raw Data'!V:V,'Sales Transactions Raw Data'!S:S,"tiktok",'Sales Transactions Raw Data'!B:B,"August",'Sales Transactions Raw Data'!A:A,2025,'Sales Transactions Raw Data'!J:J,"Finished Goods") -> 0 | F13: =SUMIFS('Sales Transactions Raw Data'!V:V,'Sales Transactions Raw Data'!S:S,"tiktok",'Sales Transactions Raw Data'!B:B,"September",'Sales Transactions Raw Data'!A:A,2025,'Sales Transactions Raw Data'!J:J,"Finished Goods") -> 0 | G13: =SUMIFS('Sales Transactions Raw Data'!V:V,'Sales Transactions Raw Data'!S:S,"tiktok",'Sales Transactions Raw Data'!B:B,"October",'Sales Transactions Raw Data'!A:A,2025,'Sales Transactions Raw Data'!J:J,"Finished Goods") -> 0 | H13: =SUMIFS('Sales Transactions Raw Data'!V:V,'Sales Transactions Raw Data'!S:S,"tiktok",'Sales Transactions Raw Data'!B:B,"November",'Sales Transactions Raw Data'!A:A,2025,'Sales Transactions Raw Data'!J:J,"Finished Goods") -> 0 | I13: =SUM(I4:I11) -> 0 | J13: =SUM(J4:J11) -> 0 | K13: =SUM(K4:K11) -> 0 | L13: =SUM(L4:L11) -> 0
A14: Channel 4901177 | C14: =SUMIFS('Sales Transactions Raw Data'!V:V,'Sales Transactions Raw Data'!S:S,"4901177",'Sales Transactions Raw Data'!B:B,"March",'Sales Transactions Raw Data'!A:A,2025,'Sales Transactions Raw Data'!J:J,"Finished Goods") -> 0 | D14: =SUMIFS('Sales Transactions Raw Data'!V:V,'Sales Transactions Raw Data'!S:S,"4901177",'Sales Transactions Raw Data'!B:B,"July",'Sales Transactions Raw Data'!A:A,2025,'Sales Transactions Raw Data'!J:J,"Finished Goods") -> 0 | E14: =SUMIFS('Sales Transactions Raw Data'!V:V,'Sales Transactions Raw Data'!S:S,"4901177",'Sales Transactions Raw Data'!B:B,"August",'Sales Transactions Raw Data'!A:A,2025,'Sales Transactions Raw Data'!J:J,"Finished Goods") -> 0 | F14: =SUMIFS('Sales Transactions Raw Data'!V:V,'Sales Transactions Raw Data'!S:S,"4901177",'Sales Transactions Raw Data'!B:B,"September",'Sales Transactions Raw Data'!A:A,2025,'Sales Transactions Raw Data'!J:J,"Finished Goods") -> 0 | G14: =SUMIFS('Sales Transactions Raw Data'!V:V,'Sales Transactions Raw Data'!S:S,"4901177",'Sales Transactions Raw Data'!B:B,"October",'Sales Transactions Raw Data'!A:A,2025,'Sales Transactions Raw Data'!J:J,"Finished Goods") -> 0 | H14: =SUMIFS('Sales Transactions Raw Data'!V:V,'Sales Transactions Raw Data'!S:S,"4901177",'Sales Transactions Raw Data'!B:B,"November",'Sales Transactions Raw Data'!A:A,2025,'Sales Transactions Raw Data'!J:J,"Finished Goods") -> 0
A15: Channel 3890849 | B15: - | C15: =SUMIFS('Sales Transactions Raw Data'!V:V,'Sales Transactions Raw Data'!S:S,"3890849",'Sales Transactions Raw Data'!B:B,"March",'Sales Transactions Raw Data'!A:A,2025,'Sales Transactions Raw Data'!J:J,"Finished Goods") -> 0 | D15: =SUMIFS('Sales Transactions Raw Data'!V:V,'Sales Transactions Raw Data'!S:S,"3890849",'Sales Transactions Raw Data'!B:B,"July",'Sales Transactions Raw Data'!A:A,2025,'Sales Transactions Raw Data'!J:J,"Finished Goods") -> 0 | E15: =SUMIFS('Sales Transactions Raw Data'!V:V,'Sales Transactions Raw Data'!S:S,"3890849",'Sales Transactions Raw Data'!B:B,"August",'Sales Transactions Raw Data'!A:A,2025,'Sales Transactions Raw Data'!J:J,"Finished Goods") -> 0 | F15: =SUMIFS('Sales Transactions Raw Data'!V:V,'Sales Transactions Raw Data'!S:S,"3890849",'Sales Transactions Raw Data'!B:B,"September",'Sales Transactions Raw Data'!A:A,2025,'Sales Transactions Raw Data'!J:J,"Finished Goods") -> 0 | G15: =SUMIFS('Sales Transactions Raw Data'!V:V,'Sales Transactions Raw Data'!S:S,"3890849",'Sales Transactions Raw Data'!B:B,"October",'Sales Transactions Raw Data'!A:A,2025,'Sales Transactions Raw Data'!J:J,"Finished Goods") -> 0 | H15: =SUMIFS('Sales Transactions Raw Data'!V:V,'Sales Transactions Raw Data'!S:S,"3890849",'Sales Transactions Raw Data'!B:B,"November",'Sales Transactions Raw Data'!A:A,2025,'Sales Transactions Raw Data'!J:J,"Finished Goods") -> 0 | I15: =IF(H13=0,"-",I13/H13-1) -> - | J15: =IF(I13=0,"-",J13/I13-1) -> - | K15: =IF(J13=0,"-",K13/J13-1) -> -
A16: Channel 2329312 | C16: =SUMIFS('Sales Transactions Raw Data'!V:V,'Sales Transactions Raw Data'!S:S,"2329312",'Sales Transactions Raw Data'!B:B,"March",'Sales Transactions Raw Data'!A:A,2025,'Sales Transactions Raw Data'!J:J,"Finished Goods") -> 0 | D16: =SUMIFS('Sales Transactions Raw Data'!V:V,'Sales Transactions Raw Data'!S:S,"2329312",'Sales Transactions Raw Data'!B:B,"July",'Sales Transactions Raw Data'!A:A,2025,'Sales Transactions Raw Data'!J:J,"Finished Goods") -> 0 | E16: =SUMIFS('Sales Transactions Raw Data'!V:V,'Sales Transactions Raw Data'!S:S,"2329312",'Sales Transactions Raw Data'!B:B,"August",'Sales Transactions Raw Data'!A:A,2025,'Sales Transactions Raw Data'!J:J,"Finished Goods") -> 0 | F16: =SUMIFS('Sales Transactions Raw Data'!V:V,'Sales Transactions Raw Data'!S:S,"2329312",'Sales Transactions Raw Data'!B:B,"September",'Sales Transactions Raw Data'!A:A,2025,'Sales Transactions Raw Data'!J:J,"Finished Goods") -> 0 | G16: =SUMIFS('Sales Transactions Raw Data'!V:V,'Sales Transactions Raw Data'!S:S,"2329312",'Sales Transactions Raw Data'!B:B,"October",'Sales Transactions Raw Data'!A:A,2025,'Sales Transactions Raw Data'!J:J,"Finished Goods") -> 0 | H16: =SUMIFS('Sales Transactions Raw Data'!V:V,'Sales Transactions Raw Data'!S:S,"2329312",'Sales Transactions Raw Data'!B:B,"November",'Sales Transactions Raw Data'!A:A,2025,'Sales Transactions Raw Data'!J:J,"Finished Goods") -> 0
A17: TOTAL REVENUE | B17: =SUMIFS('Sales Transactions Raw Data'!W:W,'Sales Transactions Raw Data'!B:B,"March",'Sales Transactions Raw Data'!A:A,2025,'Sales Transactions Raw Data'!J:J,"Finished Goods") -> 0 | C17: =SUM(C4:C16) -> 0 | D17: =SUM(D4:D16) -> 0 | E17: =SUM(E4:E16) -> 0 | F17: =SUM(F4:F16) -> 0 | G17: =SUM(G4:G16) -> 0 | H17: =SUM(H4:H16) -> 0 | I17: =SUMIFS('Sales Transactions Raw Data'!W:W,'Sales Transactions Raw Data'!B:B,"January",'Sales Transactions Raw Data'!A:A,2026,'Sales Transactions Raw Data'!J:J,"Finished Goods") -> 0 | J17: =SUMIFS('Sales Transactions Raw Data'!W:W,'Sales Transactions Raw Data'!B:B,"February",'Sales Transactions Raw Data'!A:A,2026,'Sales Transactions Raw Data'!J:J,"Finished Goods") -> 0 | K17: =SUMIFS('Sales Transactions Raw Data'!W:W,'Sales Transactions Raw Data'!B:B,"March",'Sales Transactions Raw Data'!A:A,2026,'Sales Transactions Raw Data'!J:J,"Finished Goods") -> 0 | L17: =SUM(B17:K17) -> 0
A18: GROSS PROFIT | B18: =B13-B17 -> 0 | C18: =C13-C17 -> 0 | D18: =D13-D17 -> 0 | E18: =E13-E17 -> 0 | F18: =F13-F17 -> 0 | G18: =G13-G17 -> 0 | H18: =H13-H17 -> 0 | I18: =I13-I17 -> 0 | ... L18: =L13-L17 -> 0
A19: COGS (All Finished Goods) | B19: =IF(B13=0,"-",B18/B13) -> - | C19: =SUMIFS('Sales Transactions Raw Data'!W:W,'Sales Transactions Raw Data'!B:B,"March",'Sales Transactions Raw Data'!A:A,2025,'Sales Transactions Raw Data'!J:J,"Finished Goods") -> 0 | D19: =SUMIFS('Sales Transactions Raw Data'!W:W,'Sales Transactions Raw Data'!B:B,"July",'Sales Transactions Raw Data'!A:A,2025,'Sales Transactions Raw Data'!J:J,"Finished Goods") -> 0 | E19: =SUMIFS('Sales Transactions Raw Data'!W:W,'Sales Transactions Raw Data'!B:B,"August",'Sales Transactions Raw Data'!A:A,2025,'Sales Transactions Raw Data'!J:J,"Finished Goods") -> 0 | F19: =SUMIFS('Sales Transactions Raw Data'!W:W,'Sales Transactions Raw Data'!B:B,"September",'Sales Transactions Raw Data'!A:A,2025,'Sales Transactions Raw Data'!J:J,"Finished Goods") -> 0 | G19: =SUMIFS('Sales Transactions Raw Data'!W:W,'Sales Transactions Raw Data'!B:B,"October",'Sales Transactions Raw Data'!A:A,2025,'Sales Transactions Raw Data'!J:J,"Finished Goods") -> 0 | H19: =SUMIFS('Sales Transactions Raw Data'!W:W,'Sales Transactions Raw Data'!B:B,"November",'Sales Transactions Raw Data'!A:A,2025,'Sales Transactions Raw Data'!J:J,"Finished Goods") -> 0 | I19: =IF(I13=0,"-",I18/I13) -> - | J19: =IF(J13=0,"-",J18/J13) -> - | K19: =IF(K13=0,"-",K18/K13) -> - | L19: =IF(L13=0,"-",L18/L13) -> -
A20: Gross Profit | C20: =C17-C19 -> 0 | D20: =D17-D19 -> 0 | E20: =E17-E19 -> 0 | F20: =F17-F19 -> 0 | G20: =G17-G19 -> 0 | H20: =H17-H19 -> 0
A21: Gross Margin % | C21: =IF(C17=0,"-",C20/C17) -> - | D21: =IF(D17=0,"-",D20/D17) -> - | E21: =IF(E17=0,"-",E20/E17) -> - | F21: =IF(F17=0,"-",F20/F17) -> - | G21: =IF(G17=0,"-",G20/G17) -> - | H21: =IF(H17=0,"-",H20/H17) -> -
A22: MoM Revenue Growth | C22: — | D22: =IF(C17=0,"-",D17/C17-1) -> - | E22: =IF(D17=0,"-",E17/D17-1) -> - | F22: =IF(E17=0,"-",F17/E17-1) -> - | G22: =IF(F17=0,"-",G17/F17-1) -> - | H22: =IF(G17=0,"-",H17/G17-1) -> -

Sheet Product Margin Analysis
A1: Product Margin Analysis — by Product Attributes
A2: Filtered to Finished Goods only (excludes Service items like Shipping, Discounts)
A4: BY PRODUCT (SKU) | B4: Units Sold | C4: Revenue | D4: COGS | E4: Gross Profit | F4: GM% | G4: Avg Sell Price | H4: Avg COGS/Unit
A5: 16oz Variety 12pk | B5: =SUMIFS('Sales Transactions Raw Data'!T:T,'Sales Transactions Raw Data'!G:G,"Ola-Mate-VP1-16oz-12pk",'Sales Transactions Raw Data'!J:J,"Finished Goods") -> 0 | C5: =SUMIFS('Sales Transactions Raw Data'!V:V,'Sales Transactions Raw Data'!G:G,"Ola-Mate-VP1-16oz-12pk",'Sales Transactions Raw Data'!J:J,"Finished Goods") -> 0 | D5: =SUMIFS('Sales Transactions Raw Data'!W:W,'Sales Transactions Raw Data'!G:G,"Ola-Mate-VP1-16oz-12pk",'Sales Transactions Raw Data'!J:J,"Finished Goods") -> 0 | E5: =C5-D5 -> 0 | F5: =IF(C5=0,"-",E5/C5) -> - | G5: =IF(B5=0,"-",C5/B5) -> - | H5: =IF(B5=0,"-",D5/B5) -> -
A6: 16oz Berry Coconut 12pk | B6: =SUMIFS('Sales Transactions Raw Data'!T:T,'Sales Transactions Raw Data'!G:G,"Ola-Mate-BC-16oz-12PK",'Sales Transactions Raw Data'!J:J,"Finished Goods") -> 0 | C6: =SUMIFS('Sales Transactions Raw Data'!V:V,'Sales Transactions Raw Data'!G:G,"Ola-Mate-BC-16oz-12PK",'Sales Transactions Raw Data'!J:J,"Finished Goods") -> 0 | D6: =SUMIFS('Sales Transactions Raw Data'!W:W,'Sales Transactions Raw Data'!G:G,"Ola-Mate-BC-16oz-12PK",'Sales Transactions Raw Data'!J:J,"Finished Goods") -> 0 | E6: =C6-D6 -> 0 | F6: =IF(C6=0,"-",E6/C6) -> - | G6: =IF(B6=0,"-",C6/B6) -> - | H6: =IF(B6=0,"-",D6/B6) -> -
A7: 16oz Raspberry 12pk | B7: =SUMIFS('Sales Transactions Raw Data'!T:T,'Sales Transactions Raw Data'!G:G,"Ola-Mate-R-16oz-12pk",'Sales Transactions Raw Data'!J:J,"Finished Goods") -> 0 | C7: =SUMIFS('Sales Transactions Raw Data'!V:V,'Sales Transactions Raw Data'!G:G,"Ola-Mate-R-16oz-12pk",'Sales Transactions Raw Data'!J:J,"Finished Goods") -> 0 | D7: =SUMIFS('Sales Transactions Raw Data'!W:W,'Sales Transactions Raw Data'!G:G,"Ola-Mate-R-16oz-12pk",'Sales Transactions Raw Data'!J:J,"Finished Goods") -> 0 | E7: =C7-D7 -> 0 | F7: =IF(C7=0,"-",E7/C7) -> - | G7: =IF(B7=0,"-",C7/B7) -> - | H7: =IF(B7=0,"-",D7/B7) -> -
A8: 16oz Grapefruit Ginger 12pk | B8: =SUMIFS('Sales Transactions Raw Data'!T:T,'Sales Transactions Raw Data'!G:G,"Ola-Mate-GG-16oz-12pk",'Sales Transactions Raw Data'!J:J,"Finished Goods") -> 0 | C8: =SUMIFS('Sales Transactions Raw Data'!V:V,'Sales Transactions Raw Data'!G:G,"Ola-Mate-GG-16oz-12pk",'Sales Transactions Raw Data'!J:J,"Finished Goods") -> 0 | D8: =SUMIFS('Sales Transactions Raw Data'!W:W,'Sales Transactions Raw Data'!G:G,"Ola-Mate-GG-16oz-12pk",'Sales Transactions Raw Data'!J:J,"Finished Goods") -> 0 | E8: =C8-D8 -> 0 | F8: =IF(C8=0,"-",E8/C8) -> - | G8: =IF(B8=0,"-",C8/B8) -> - | H8: =IF(B8=0,"-",D8/B8) -> -
A9: 16oz Starter 4pk | B9: =SUMIFS('Sales Transactions Raw Data'!T:T,'Sales Transactions Raw Data'!G:G,"Ola-Mate-SP1-16oz-4pk",'Sales Transactions Raw Data'!J:J,"Finished Goods") -> 0 | C9: =SUMIFS('Sales Transactions Raw Data'!V:V,'Sales Transactions Raw Data'!G:G,"Ola-Mate-SP1-16oz-4pk",'Sales Transactions Raw Data'!J:J,"Finished Goods") -> 0 | D9: =SUMIFS('Sales Transactions Raw Data'!W:W,'Sales Transactions Raw Data'!G:G,"Ola-Mate-SP1-16oz-4pk",'Sales Transactions Raw Data'!J:J,"Finished Goods") -> 0 | E9: =C9-D9 -> 0 | F9: =IF(C9=0,"-",E9/C9) -> - | G9: =IF(B9=0,"-",C9/B9) -> - | H9: =IF(B9=0,"-",D9/B9) -> -
A10: 1can (BC/GG/R) - loose | B10: =SUMIFS('Sales Transactions Raw Data'!T:T,'Sales Transactions Raw Data'!G:G,"Ola-Mate-BC-16oz-1can",'Sales Transactions Raw Data'!J:J,"Finished Goods")+SUMIFS('Sales Transactions Raw Data'!T:T,'Sales Transactions Raw Data'!G:G,"Ola-Mate-GG-16oz-1can",'Sales Transactions Raw Data'!J:J,"Finished Goods")+SUMIFS('Sales Transactions Raw Data'!T:T,'Sales Transactions Raw Data'!G:G,"Ola-Mate-R-16oz-1can",'Sales Transactions Raw Data'!J:J,"Finished Goods") -> 0 | C10: =SUMIFS('Sales Transactions Raw Data'!V:V,'Sales Transactions Raw Data'!G:G,"Ola-Mate-BC-16oz-1can",'Sales Transactions Raw Data'!J:J,"Finished Goods")+SUMIFS('Sales Transactions Raw Data'!V:V,'Sales Transactions Raw Data'!G:G,"Ola-Mate-GG-16oz-1can",'Sales Transactions Raw Data'!J:J,"Finished Goods")+SUMIFS('Sales Transactions Raw Data'!V:V,'Sales Transactions Raw Data'!G:G,"Ola-Mate-R-16oz-1can",'Sales Transactions Raw Data'!J:J,"Finished Goods") -> 0 | D10: =SUMIFS('Sales Transactions Raw Data'!W:W,'Sales Transactions Raw Data'!G:G,"Ola-Mate-BC-16oz-1can",'Sales Transactions Raw Data'!J:J,"Finished Goods")+SUMIFS('Sales Transactions Raw Data'!W:W,'Sales Transactions Raw Data'!G:G,"Ola-Mate-GG-16oz-1can",'Sales Transactions Raw Data'!J:J,"Finished Goods")+SUMIFS('Sales Transactions Raw Data'!W:W,'Sales Transactions Raw Data'!G:G,"Ola-Mate-R-16oz-1can",'Sales Transactions Raw Data'!J:J,"Finished Goods") -> 0 | E10: =C10-D10 -> 0 | F10: =IF(C10=0,"-",E10/C10) -> - | G10: =IF(B10=0,"-",C10/B10) -> - | H10: =IF(B10=0,"-",D10/B10) -> -
A11: Powder Blends (new) | B11: =SUMIFS('Sales Transactions Raw Data'!T:T,'Sales Transactions Raw Data'!G:G,"Ola-Mate-POW-*",'Sales Transactions Raw Data'!J:J,"Finished Goods") -> 0 | C11: =SUMIFS('Sales Transactions Raw Data'!V:V,'Sales Transactions Raw Data'!G:G,"Ola-Mate-POW-*",'Sales Transactions Raw Data'!J:J,"Finished Goods") -> 0 | D11: =SUMIFS('Sales Transactions Raw Data'!W:W,'Sales Transactions Raw Data'!G:G,"Ola-Mate-POW-*",'Sales Transactions Raw Data'!J:J,"Finished Goods") -> 0 | E11: =C11-D11 -> 0 | F11: =IF(C11=0,"-",E11/C11) -> - | G11: =IF(B11=0,"-",C11/B11) -> - | H11: =IF(B11=0,"-",D11/B11) -> -
A12: TOTAL PRODUCTS | B12: =SUM(B5:B11) -> 0 | C12: =SUM(C5:C11) -> 0 | D12: =SUM(D5:D11) -> 0 | E12: =C12-D12 -> 0 | F12: =IF(C12=0,"-",E12/C12) -> - | G12: =IF(B12=0,"-",C12/B12) -> - | H12: =IF(B12=0,"-",D12/B12) -> -
A14: BY CATEGORY | B14: Units Sold | C14: Revenue | D14: COGS | E14: Gross Profit | F14: GM% | G14: Revenue % | H14: Avg Sell Price
A15: Finished Goods | B15: =SUMIFS('Sales Transactions Raw Data'!T:T,'Sales Transactions Raw Data'!J:J,"Finished Goods") -> 0 | C15: =SUMIFS('Sales Transactions Raw Data'!V:V,'Sales Transactions Raw Data'!J:J,"Finished Goods") -> 0 | D15: =SUMIFS('Sales Transactions Raw Data'!W:W,'Sales Transactions Raw Data'!J:J,"Finished Goods") -> 0 | E15: =C15-D15 -> 0 | F15: =IF(C15=0,"-",E15/C15) -> - | G15: =IF(C$17=0,"-",C15/C$17) -> - | H15: =IF(B15=0,"-",C15/B15) -> -
A16: Service (Shipping/Discounts/POS) | B16: =SUMIFS('Sales Transactions Raw Data'!T:T,'Sales Transactions Raw Data'!J:J,"Service") -> 0 | C16: =SUMIFS('Sales Transactions Raw Data'!V:V,'Sales Transactions Raw Data'!J:J,"Service") -> 0 | D16: =SUMIFS('Sales Transactions Raw Data'!W:W,'Sales Transactions Raw Data'!J:J,"Service") -> 0 | E16: =C16-D16 -> 0 | F16: =IF(C16=0,"-",E16/C16) -> - | G16: =IF(C$17=0,"-",C16/C$17) -> - | H16: =IF(B16=0,"-",C16/B16) -> -
A17: GRAND TOTAL | B17: =B15+B16 -> 0 | C17: =C15+C16 -> 0 | D17: =D15+D16 -> 0 | E17: =C17-D17 -> 0 | F17: =IF(C17=0,"-",E17/C17) -> - | G17: 1

Sheet COGS & Profitability by Channel
A1: COGS & Profitability by Product × Sales Channel
A2: Finished Goods only | All time periods combined
A4: REVENUE BY CHANNEL × PRODUCT | B4: Amazon | C4: Amazon Retail | D4: Shopify Web | E4: Shopify POS | F4: Shopify Admin | G4: Subs (contract) | H4: Subs (checkout) | I4: Wholesale 296... | J4: Faire | K4: TikTok | L4: Ch 4901177 | M4: Ch 3890849 | N4: Total
